<?xml version="1.0" ?>
<!-- Generated using onshape-to-robot -->
<!-- Onshape document_id: 16c9706360b5ad34f9c8db49 -->
<mujoco model="simulation">
  <compiler angle="radian" meshdir="assets" autolimits="true"/>
  <default>
    <default class="simulation">
      <joint frictionloss="0.1" armature="0.005"/>
      <position kp="50" dampratio="1"/>
      <default class="visual">
        <geom type="mesh" contype="0" conaffinity="0" group="2"/>
      </default>
      <default class="collision">
        <geom group="3"/>
      </default>
    </default>
  </default>
  <!-- Additional sensors.xml -->
  <sensor>
    <accelerometer name="accel_sensor" site="imu_site"/>
    <gyro name="gyro_sensor" site="imu_site"/>
  </sensor>
  <!-- Additional joints_properties.xml -->
  <default>
    <default class="sts3215">
      <geom contype="0" conaffinity="0"/>
      <joint damping="0.60" frictionloss="0.052" armature="0.028"/>
      <position kp="17.8" kv="0.0" forcerange="-3.35 3.35"/>
    </default>
    <default class="backlash">
      <!-- +/- 0.5° of backlash -->
      <joint damping="0.01" frictionloss="0" armature="0.01" limited="true" range="-0.008726646259971648 0.008726646259971648"/>
    </default>
  </default>
  <worldbody>
    <!-- Link lamparm__base_elbow -->
    <body name="lamparm__base_elbow" pos="0 0 0" quat="1 0 0 0" childclass="simulation">
      <freejoint name="lamparm__base_elbow_freejoint"/>
      <inertial pos="-0.0229181 0.00297443 0.185358" mass="0.134549" fullinertia="0.000472889 0.000498762 8.10272e-05 1.27811e-05 0.000145734 -5.93489e-05"/>
      <!-- Part lamparm__base_elbow -->
      <geom type="mesh" class="visual" pos="-0.0201675 0.024048 0.201642" quat="0.186925 -0.176272 0.0341156 0.965828" mesh="lamparm__base_elbow" material="lamparm__base_elbow_material"/>
      <geom type="mesh" class="collision" pos="-0.0201675 0.024048 0.201642" quat="0.186925 -0.176272 0.0341156 0.965828" mesh="lamparm__base_elbow" material="lamparm__base_elbow_material"/>
      <!-- Link scs215_v5 -->
      <body name="scs215_v5" pos="0.0154636 0.00756357 0.08031" quat="0.585897 -0.395884 0.585897 0.395884">
        <!-- Joint from lamparm__base_elbow to scs215_v5 -->
        <joint axis="0 0 1" name="2" type="hinge" range="-1.931840663764446 1.209751989825347" class="sts3215"/>
        <inertial pos="0.0180556 0.000605864 -0.0197123" mass="0.0852562" fullinertia="8.7923e-06 1.82503e-05 1.4956e-05 -3.86833e-07 9.72694e-07 6.73016e-08"/>
        <!-- Part 金属舵盘_驱动__v2 -->
        <geom type="mesh" class="visual" pos="-0.01 0 -0.027" quat="0.707107 0.707107 -0 1.04589e-31" mesh="金属舵盘_驱动__v2" material="金属舵盘_驱动__v2_material"/>
        <geom type="mesh" class="collision" pos="-0.01 0 -0.027" quat="0.707107 0.707107 -0 1.04589e-31" mesh="金属舵盘_驱动__v2" material="金属舵盘_驱动__v2_material"/>
        <!-- Part 金属舵盘_从动__v2 -->
        <geom type="mesh" class="visual" pos="0.01 -4.63171e-16 -0.05905" quat="2.57658e-15 2.4844e-15 0.707107 -0.707107" mesh="金属舵盘_从动__v2" material="金属舵盘_从动__v2_material"/>
        <geom type="mesh" class="collision" pos="0.01 -4.63171e-16 -0.05905" quat="2.57658e-15 2.4844e-15 0.707107 -0.707107" mesh="金属舵盘_从动__v2" material="金属舵盘_从动__v2_material"/>
        <!-- Part pcb_chazuo_92 -->
        <geom type="mesh" class="visual" pos="0.0255 6.59195e-17 -0.0096" quat="0.707107 0.707107 -0 1.04589e-31" mesh="pcb_chazuo_92" material="pcb_chazuo_92_material"/>
        <geom type="mesh" class="collision" pos="0.0255 6.59195e-17 -0.0096" quat="0.707107 0.707107 -0 1.04589e-31" mesh="pcb_chazuo_92" material="pcb_chazuo_92_material"/>
        <!-- Part xg_ziji_16 -->
        <geom type="mesh" class="visual" pos="0.0255 6.59195e-17 -0.0096" quat="0.707107 0.707107 -0 1.04589e-31" mesh="xg_ziji_16" material="xg_ziji_16_material"/>
        <geom type="mesh" class="collision" pos="0.0255 6.59195e-17 -0.0096" quat="0.707107 0.707107 -0 1.04589e-31" mesh="xg_ziji_16" material="xg_ziji_16_material"/>
        <!-- Part ge_27 -->
        <geom type="mesh" class="visual" pos="-1.249e-16 6.93889e-17 -0.0156" quat="0 1 0 0" mesh="ge_27" material="ge_27_material"/>
        <geom type="mesh" class="collision" pos="-1.249e-16 6.93889e-17 -0.0156" quat="0 1 0 0" mesh="ge_27" material="ge_27_material"/>
        <!-- Part sg_ziji_15 -->
        <geom type="mesh" class="visual" pos="0.0255 6.59195e-17 -0.0096" quat="0.707107 0.707107 -0 1.04589e-31" mesh="sg_ziji_15" material="sg_ziji_15_material"/>
        <geom type="mesh" class="collision" pos="0.0255 6.59195e-17 -0.0096" quat="0.707107 0.707107 -0 1.04589e-31" mesh="sg_ziji_15" material="sg_ziji_15_material"/>
        <!-- Part zk_122 -->
        <geom type="mesh" class="visual" pos="0.0255 6.59195e-17 -0.0096" quat="0.707107 0.707107 -0 1.04589e-31" mesh="zk_122" material="zk_122_material"/>
        <geom type="mesh" class="collision" pos="0.0255 6.59195e-17 -0.0096" quat="0.707107 0.707107 -0 1.04589e-31" mesh="zk_122" material="zk_122_material"/>
        <!-- Part motor_1723_3 -->
        <geom type="mesh" class="visual" pos="0.0255 0.00125 -0.03245" quat="0.5 0.5 0.5 0.5" mesh="motor_1723_3" material="motor_1723_3_material"/>
        <geom type="mesh" class="collision" pos="0.0255 0.00125 -0.03245" quat="0.5 0.5 0.5 0.5" mesh="motor_1723_3" material="motor_1723_3_material"/>
      </body>
    </body>
    <!-- Link lamparm__wrist_head -->
    <body name="lamparm__wrist_head" pos="0 0 0" quat="1 0 0 0" childclass="simulation">
      <freejoint name="lamparm__wrist_head_freejoint"/>
      <inertial pos="0.00827959 -0.0103008 0.0499315" mass="0.0101242" fullinertia="2.18249e-06 1.57724e-06 2.87377e-06 -2.90349e-07 -5.3858e-09 -1.33928e-08"/>
      <!-- Part lamparm__wrist_head -->
      <geom type="mesh" class="visual" pos="0.0083 -0.01025 0.0392" quat="0.190013 5.21098e-16 2.06035e-17 0.981782" mesh="lamparm__wrist_head" material="lamparm__wrist_head_material"/>
      <geom type="mesh" class="collision" pos="0.0083 -0.01025 0.0392" quat="0.190013 5.21098e-16 2.06035e-17 0.981782" mesh="lamparm__wrist_head" material="lamparm__wrist_head_material"/>
      <!-- Link scs215_v5_2 -->
      <body name="scs215_v5_2" pos="0.0083 -0.01025 0.0392" quat="0.190013 5.21098e-16 2.06035e-17 0.981782">
        <!-- Joint from lamparm__wrist_head to scs215_v5_2 -->
        <joint axis="0 0 1" name="1" type="hinge" range="-5.09473967719376 1.188445629985826" class="sts3215"/>
        <inertial pos="0.0165258 0.00729871 -0.0197123" mass="0.0852562" fullinertia="1.03767e-05 1.66659e-05 1.4956e-05 -3.55311e-06 8.77345e-07 4.25356e-07"/>
        <!-- Part 金属舵盘_驱动__v2_2 -->
        <geom type="mesh" class="visual" pos="-0.0092779 -0.00373102 -0.027" quat="0.694224 0.694224 0.134359 0.134359" mesh="金属舵盘_驱动__v2" material="金属舵盘_驱动__v2_material"/>
        <geom type="mesh" class="collision" pos="-0.0092779 -0.00373102 -0.027" quat="0.694224 0.694224 0.134359 0.134359" mesh="金属舵盘_驱动__v2" material="金属舵盘_驱动__v2_material"/>
        <!-- Part 金属舵盘_从动__v2_2 -->
        <geom type="mesh" class="visual" pos="0.0092779 0.00373102 -0.05905" quat="0.134359 -0.134359 0.694224 -0.694224" mesh="金属舵盘_从动__v2" material="金属舵盘_从动__v2_material"/>
        <geom type="mesh" class="collision" pos="0.0092779 0.00373102 -0.05905" quat="0.134359 -0.134359 0.694224 -0.694224" mesh="金属舵盘_从动__v2" material="金属舵盘_从动__v2_material"/>
        <!-- Part pcb_chazuo_92_2 -->
        <geom type="mesh" class="visual" pos="0.0236586 0.00951411 -0.0096" quat="0.694224 0.694224 0.134359 0.134359" mesh="pcb_chazuo_92" material="pcb_chazuo_92_material"/>
        <geom type="mesh" class="collision" pos="0.0236586 0.00951411 -0.0096" quat="0.694224 0.694224 0.134359 0.134359" mesh="pcb_chazuo_92" material="pcb_chazuo_92_material"/>
        <!-- Part xg_ziji_16_2 -->
        <geom type="mesh" class="visual" pos="0.0236586 0.00951411 -0.0096" quat="0.694224 0.694224 0.134359 0.134359" mesh="xg_ziji_16" material="xg_ziji_16_material"/>
        <geom type="mesh" class="collision" pos="0.0236586 0.00951411 -0.0096" quat="0.694224 0.694224 0.134359 0.134359" mesh="xg_ziji_16" material="xg_ziji_16_material"/>
        <!-- Part ge_27_2 -->
        <geom type="mesh" class="visual" pos="-6.93889e-17 2.1684e-17 -0.0156" quat="6.87769e-16 -0.981782 -0.190013 1.05019e-15" mesh="ge_27" material="ge_27_material"/>
        <geom type="mesh" class="collision" pos="-6.93889e-17 2.1684e-17 -0.0156" quat="6.87769e-16 -0.981782 -0.190013 1.05019e-15" mesh="ge_27" material="ge_27_material"/>
        <!-- Part sg_ziji_15_2 -->
        <geom type="mesh" class="visual" pos="0.0236586 0.00951411 -0.0096" quat="0.694224 0.694224 0.134359 0.134359" mesh="sg_ziji_15" material="sg_ziji_15_material"/>
        <geom type="mesh" class="collision" pos="0.0236586 0.00951411 -0.0096" quat="0.694224 0.694224 0.134359 0.134359" mesh="sg_ziji_15" material="sg_ziji_15_material"/>
        <!-- Part zk_122_2 -->
        <geom type="mesh" class="visual" pos="0.0236586 0.00951411 -0.0096" quat="0.694224 0.694224 0.134359 0.134359" mesh="zk_122" material="zk_122_material"/>
        <geom type="mesh" class="collision" pos="0.0236586 0.00951411 -0.0096" quat="0.694224 0.694224 0.134359 0.134359" mesh="zk_122" material="zk_122_material"/>
        <!-- Part motor_1723_3_2 -->
        <geom type="mesh" class="visual" pos="0.0231923 0.0106739 -0.03245" quat="0.395884 0.395884 0.585897 0.585897" mesh="motor_1723_3" material="motor_1723_3_material"/>
        <geom type="mesh" class="collision" pos="0.0231923 0.0106739 -0.03245" quat="0.395884 0.395884 0.585897 0.585897" mesh="motor_1723_3" material="motor_1723_3_material"/>
        <!-- Frame imu_site -->
        <site group="3" name="imu_site" pos="-4.51028e-17 -1.82146e-17 -0.0378" quat="5.4239e-16 0.190013 -0.981782 -1.7387e-15"/>
      </body>
    </body>
    <!-- Link lamparm__elbow_wrist -->
    <body name="lamparm__elbow_wrist" pos="0 0 0" quat="1 0 0 0" childclass="simulation">
      <freejoint name="lamparm__elbow_wrist_freejoint"/>
      <inertial pos="-0.144104 0.0515418 0.248908" mass="0.107291" fullinertia="0.000121928 0.000236114 0.000188338 4.83306e-05 -0.000107412 4.00557e-05"/>
      <!-- Part lamparm__elbow_wrist -->
      <geom type="mesh" class="visual" pos="-0.149427 0.0321877 0.247913" quat="0.451772 -0.168701 -0.871663 -0.0874355" mesh="lamparm__elbow_wrist" material="lamparm__elbow_wrist_material"/>
      <geom type="mesh" class="collision" pos="-0.149427 0.0321877 0.247913" quat="0.451772 -0.168701 -0.871663 -0.0874355" mesh="lamparm__elbow_wrist" material="lamparm__elbow_wrist_material"/>
      <!-- Link scs215_v5_3 -->
      <body name="scs215_v5_3" pos="-0.0718619 0.0433005 0.303327" quat="0.200162 -0.438741 -0.554533 -0.678185">
        <!-- Joint from lamparm__elbow_wrist to scs215_v5_3 -->
        <joint axis="0 0 1" name="3" type="hinge" range="-2.609605990859412 0.5319866627303811" class="sts3215"/>
        <inertial pos="-0.0158677 0.00863651 -0.0197123" mass="0.0852562" fullinertia="1.08876e-05 1.61549e-05 1.4956e-05 3.94674e-06 -8.72407e-07 4.35395e-07"/>
        <!-- Part 金属舵盘_驱动__v2_3 -->
        <geom type="mesh" class="visual" pos="0.00861801 -0.00507246 -0.027" quat="0.185876 0.185876 0.682239 0.682239" mesh="金属舵盘_驱动__v2" material="金属舵盘_驱动__v2_material"/>
        <geom type="mesh" class="collision" pos="0.00861801 -0.00507246 -0.027" quat="0.185876 0.185876 0.682239 0.682239" mesh="金属舵盘_驱动__v2" material="金属舵盘_驱动__v2_material"/>
        <!-- Part 金属舵盘_从动__v2_3 -->
        <geom type="mesh" class="visual" pos="-0.00861801 0.00507246 -0.05905" quat="0.682239 -0.682239 0.185876 -0.185876" mesh="金属舵盘_从动__v2" material="金属舵盘_从动__v2_material"/>
        <geom type="mesh" class="collision" pos="-0.00861801 0.00507246 -0.05905" quat="0.682239 -0.682239 0.185876 -0.185876" mesh="金属舵盘_从动__v2" material="金属舵盘_从动__v2_material"/>
        <!-- Part pcb_chazuo_92_3 -->
        <geom type="mesh" class="visual" pos="-0.0219759 0.0129348 -0.0096" quat="0.185876 0.185876 0.682239 0.682239" mesh="pcb_chazuo_92" material="pcb_chazuo_92_material"/>
        <geom type="mesh" class="collision" pos="-0.0219759 0.0129348 -0.0096" quat="0.185876 0.185876 0.682239 0.682239" mesh="pcb_chazuo_92" material="pcb_chazuo_92_material"/>
        <!-- Part xg_ziji_16_3 -->
        <geom type="mesh" class="visual" pos="-0.0219759 0.0129348 -0.0096" quat="0.185876 0.185876 0.682239 0.682239" mesh="xg_ziji_16" material="xg_ziji_16_material"/>
        <geom type="mesh" class="collision" pos="-0.0219759 0.0129348 -0.0096" quat="0.185876 0.185876 0.682239 0.682239" mesh="xg_ziji_16" material="xg_ziji_16_material"/>
        <!-- Part ge_27_3 -->
        <geom type="mesh" class="visual" pos="-2.77556e-15 6.4948e-15 -0.0156" quat="1.44711e-14 0.262868 0.964832 -1.85113e-14" mesh="ge_27" material="ge_27_material"/>
        <geom type="mesh" class="collision" pos="-2.77556e-15 6.4948e-15 -0.0156" quat="1.44711e-14 0.262868 0.964832 -1.85113e-14" mesh="ge_27" material="ge_27_material"/>
        <!-- Part sg_ziji_15_3 -->
        <geom type="mesh" class="visual" pos="-0.0219759 0.0129348 -0.0096" quat="0.185876 0.185876 0.682239 0.682239" mesh="sg_ziji_15" material="sg_ziji_15_material"/>
        <geom type="mesh" class="collision" pos="-0.0219759 0.0129348 -0.0096" quat="0.185876 0.185876 0.682239 0.682239" mesh="sg_ziji_15" material="sg_ziji_15_material"/>
        <!-- Part zk_122_3 -->
        <geom type="mesh" class="visual" pos="-0.0219759 0.0129348 -0.0096" quat="0.185876 0.185876 0.682239 0.682239" mesh="zk_122" material="zk_122_material"/>
        <geom type="mesh" class="collision" pos="-0.0219759 0.0129348 -0.0096" quat="0.185876 0.185876 0.682239 0.682239" mesh="zk_122" material="zk_122_material"/>
        <!-- Part motor_1723_3_3 -->
        <geom type="mesh" class="visual" pos="-0.02261 0.0118575 -0.03245" quat="0.350982 0.350982 -0.61385 -0.61385" mesh="motor_1723_3" material="motor_1723_3_material"/>
        <geom type="mesh" class="collision" pos="-0.02261 0.0118575 -0.03245" quat="0.350982 0.350982 -0.61385 -0.61385" mesh="motor_1723_3" material="motor_1723_3_material"/>
      </body>
    </body>
    <!-- Link lamparm__wrist_head_2 -->
    <body name="lamparm__wrist_head_2" pos="0 0 0" quat="1 0 0 0" childclass="simulation">
      <freejoint name="lamparm__wrist_head_2_freejoint"/>
      <inertial pos="-0.222648 0.0973951 0.190378" mass="0.0101242" fullinertia="2.50556e-06 1.63778e-06 2.49016e-06 -4.30575e-07 2.47192e-07 -1.10648e-07"/>
      <!-- Part lamparm__wrist_head_2 -->
      <geom type="mesh" class="visual" pos="-0.214533 0.0940727 0.196565" quat="0.451637 -0.16736 -0.871922 -0.0881301" mesh="lamparm__wrist_head" material="lamparm__wrist_head_material"/>
      <geom type="mesh" class="collision" pos="-0.214533 0.0940727 0.196565" quat="0.451637 -0.16736 -0.871922 -0.0881301" mesh="lamparm__wrist_head" material="lamparm__wrist_head_material"/>
      <!-- Link scs215_v5_4 -->
      <body name="scs215_v5_4" pos="-0.214533 0.0940727 0.196565" quat="0.451637 -0.16736 -0.871922 -0.0881301">
        <!-- Joint from lamparm__wrist_head_2 to scs215_v5_4 -->
        <joint axis="0 0 1" name="4" type="hinge" range="-3.14466826187895 3.1385170453006364" class="sts3215"/>
        <inertial pos="0.000661393 -0.0180537 -0.0197123" mass="0.0852562" fullinertia="1.82478e-05 8.79477e-06 1.4956e-05 4.15915e-07 7.02929e-08 -9.72482e-07"/>
        <!-- Part 金属舵盘_驱动__v2_4 -->
        <geom type="mesh" class="visual" pos="-3.0756e-05 0.00999995 -0.027" quat="0.500768 0.500768 -0.499231 -0.499231" mesh="金属舵盘_驱动__v2" material="金属舵盘_驱动__v2_material"/>
        <geom type="mesh" class="collision" pos="-3.0756e-05 0.00999995 -0.027" quat="0.500768 0.500768 -0.499231 -0.499231" mesh="金属舵盘_驱动__v2" material="金属舵盘_驱动__v2_material"/>
        <!-- Part 金属舵盘_从动__v2_4 -->
        <geom type="mesh" class="visual" pos="3.0756e-05 -0.00999995 -0.05905" quat="0.499231 -0.499231 -0.500768 0.500768" mesh="金属舵盘_从动__v2" material="金属舵盘_从动__v2_material"/>
        <geom type="mesh" class="collision" pos="3.0756e-05 -0.00999995 -0.05905" quat="0.499231 -0.499231 -0.500768 0.500768" mesh="金属舵盘_从动__v2" material="金属舵盘_从动__v2_material"/>
        <!-- Part pcb_chazuo_92_4 -->
        <geom type="mesh" class="visual" pos="7.84279e-05 -0.0254999 -0.0096" quat="0.500768 0.500768 -0.499231 -0.499231" mesh="pcb_chazuo_92" material="pcb_chazuo_92_material"/>
        <geom type="mesh" class="collision" pos="7.84279e-05 -0.0254999 -0.0096" quat="0.500768 0.500768 -0.499231 -0.499231" mesh="pcb_chazuo_92" material="pcb_chazuo_92_material"/>
        <!-- Part xg_ziji_16_4 -->
        <geom type="mesh" class="visual" pos="7.84279e-05 -0.0254999 -0.0096" quat="0.500768 0.500768 -0.499231 -0.499231" mesh="xg_ziji_16" material="xg_ziji_16_material"/>
        <geom type="mesh" class="collision" pos="7.84279e-05 -0.0254999 -0.0096" quat="0.500768 0.500768 -0.499231 -0.499231" mesh="xg_ziji_16" material="xg_ziji_16_material"/>
        <!-- Part ge_27_4 -->
        <geom type="mesh" class="visual" pos="1.66533e-16 3.05311e-16 -0.0156" quat="1.48824e-14 0.708193 -0.706019 -1.86072e-14" mesh="ge_27" material="ge_27_material"/>
        <geom type="mesh" class="collision" pos="1.66533e-16 3.05311e-16 -0.0156" quat="1.48824e-14 0.708193 -0.706019 -1.86072e-14" mesh="ge_27" material="ge_27_material"/>
        <!-- Part sg_ziji_15_4 -->
        <geom type="mesh" class="visual" pos="7.84279e-05 -0.0254999 -0.0096" quat="0.500768 0.500768 -0.499231 -0.499231" mesh="sg_ziji_15" material="sg_ziji_15_material"/>
        <geom type="mesh" class="collision" pos="7.84279e-05 -0.0254999 -0.0096" quat="0.500768 0.500768 -0.499231 -0.499231" mesh="sg_ziji_15" material="sg_ziji_15_material"/>
        <!-- Part zk_122_4 -->
        <geom type="mesh" class="visual" pos="7.84279e-05 -0.0254999 -0.0096" quat="0.500768 0.500768 -0.499231 -0.499231" mesh="zk_122" material="zk_122_material"/>
        <geom type="mesh" class="collision" pos="7.84279e-05 -0.0254999 -0.0096" quat="0.500768 0.500768 -0.499231 -0.499231" mesh="zk_122" material="zk_122_material"/>
        <!-- Part motor_1723_3_4 -->
        <geom type="mesh" class="visual" pos="0.00132842 -0.025496 -0.03245" quat="0.707106 0.707106 0.00108739 0.00108739" mesh="motor_1723_3" material="motor_1723_3_material"/>
        <geom type="mesh" class="collision" pos="0.00132842 -0.025496 -0.03245" quat="0.707106 0.707106 0.00108739 0.00108739" mesh="motor_1723_3" material="motor_1723_3_material"/>
      </body>
    </body>
    <!-- Link scs215_v5_5 -->
    <body name="scs215_v5_5" pos="0 0 0" quat="1 0 0 0" childclass="simulation">
      <freejoint name="scs215_v5_5_freejoint"/>
      <inertial pos="-0.232145 0.101705 0.18377" mass="0.0852562" fullinertia="1.21537e-05 1.51057e-05 1.47392e-05 3.77963e-07 -4.48721e-06 1.13263e-06"/>
      <!-- Part 金属舵盘_驱动__v2_5 -->
      <geom type="mesh" class="visual" pos="-0.250382 0.116896 0.167119" quat="0.0560241 0.935897 -0.180659 0.297186" mesh="金属舵盘_驱动__v2" material="金属舵盘_驱动__v2_material"/>
      <geom type="mesh" class="collision" pos="-0.250382 0.116896 0.167119" quat="0.0560241 0.935897 -0.180659 0.297186" mesh="金属舵盘_驱动__v2" material="金属舵盘_驱动__v2_material"/>
      <!-- Part 金属舵盘_从动__v2_5 -->
      <geom type="mesh" class="visual" pos="-0.223315 0.140555 0.17873" quat="0.297186 0.180659 0.935897 -0.0560241" mesh="金属舵盘_从动__v2" material="金属舵盘_从动__v2_material"/>
      <geom type="mesh" class="collision" pos="-0.223315 0.140555 0.17873" quat="0.297186 0.180659 0.935897 -0.0560241" mesh="金属舵盘_从动__v2" material="金属舵盘_从动__v2_material"/>
      <!-- Part pcb_chazuo_92_5 -->
      <geom type="mesh" class="visual" pos="-0.229933 0.0899185 0.187541" quat="0.0560241 0.935897 -0.180659 0.297186" mesh="pcb_chazuo_92" material="pcb_chazuo_92_material"/>
      <geom type="mesh" class="collision" pos="-0.229933 0.0899185 0.187541" quat="0.0560241 0.935897 -0.180659 0.297186" mesh="pcb_chazuo_92" material="pcb_chazuo_92_material"/>
      <!-- Part xg_ziji_16_5 -->
      <geom type="mesh" class="visual" pos="-0.229933 0.0899185 0.187541" quat="0.0560241 0.935897 -0.180659 0.297186" mesh="xg_ziji_16" material="xg_ziji_16_material"/>
      <geom type="mesh" class="collision" pos="-0.229933 0.0899185 0.187541" quat="0.0560241 0.935897 -0.180659 0.297186" mesh="xg_ziji_16" material="xg_ziji_16_material"/>
      <!-- Part ge_27_5 -->
      <geom type="mesh" class="visual" pos="-0.247035 0.103263 0.172855" quat="0.622164 -0.701394 -0.0823972 -0.337887" mesh="ge_27" material="ge_27_material"/>
      <geom type="mesh" class="collision" pos="-0.247035 0.103263 0.172855" quat="0.622164 -0.701394 -0.0823972 -0.337887" mesh="ge_27" material="ge_27_material"/>
      <!-- Part sg_ziji_15_5 -->
      <geom type="mesh" class="visual" pos="-0.229933 0.0899185 0.187541" quat="0.0560241 0.935897 -0.180659 0.297186" mesh="sg_ziji_15" material="sg_ziji_15_material"/>
      <geom type="mesh" class="collision" pos="-0.229933 0.0899185 0.187541" quat="0.0560241 0.935897 -0.180659 0.297186" mesh="sg_ziji_15" material="sg_ziji_15_material"/>
      <!-- Part zk_122_5 -->
      <geom type="mesh" class="visual" pos="-0.229933 0.0899185 0.187541" quat="0.0560241 0.935897 -0.180659 0.297186" mesh="zk_122" material="zk_122_material"/>
      <geom type="mesh" class="collision" pos="-0.229933 0.0899185 0.187541" quat="0.0560241 0.935897 -0.180659 0.297186" mesh="zk_122" material="zk_122_material"/>
      <!-- Part motor_1723_3_5 -->
      <geom type="mesh" class="visual" pos="-0.222115 0.111399 0.18862" quat="0.16736 0.451637 -0.0881301 0.871922" mesh="motor_1723_3" material="motor_1723_3_material"/>
      <geom type="mesh" class="collision" pos="-0.222115 0.111399 0.18862" quat="0.16736 0.451637 -0.0881301 0.871922" mesh="motor_1723_3" material="motor_1723_3_material"/>
      <!-- Link lamphead -->
      <body name="lamphead" pos="-0.25283 0.0887792 0.172816" quat="0.622164 -0.701394 -0.0823972 -0.337887">
        <!-- Joint from scs215_v5_5 to lamphead -->
        <joint axis="0 0 1" name="5" type="hinge" range="-2.1841514133949023 0.9574412401948911" class="sts3215"/>
        <inertial pos="-0.0646673 -0.0451799 0.0186249" mass="0.0833107" fullinertia="0.000138437 0.000147289 0.000170035 -1.20464e-05 -4.1948e-10 1.29183e-10"/>
        <!-- Part lamphead -->
        <geom type="mesh" class="visual" pos="-0.0020443 -0.00143904 0.03925" quat="0.325724 0.325724 0.627617 0.627617" mesh="lamphead" material="lamphead_material"/>
        <geom type="mesh" class="collision" pos="-0.0020443 -0.00143904 0.03925" quat="0.325724 0.325724 0.627617 0.627617" mesh="lamphead" material="lamphead_material"/>
        <!-- Frame camera -->
        <site group="3" name="camera" pos="-0.10999 -0.0319989 0.018625" quat="0.627617 0.627617 -0.325724 -0.325724"/>
      </body>
    </body>
    <!-- Link lamp_base -->
    <body name="lamp_base" pos="0 0 0" quat="1 0 0 0" childclass="simulation">
      <freejoint name="lamp_base_freejoint"/>
      <inertial pos="-0.00977932 -0.0138894 0.0149535" mass="0.363855" fullinertia="0.000661257 0.000822089 0.00144905 4.24141e-05 -8.60647e-06 -9.71008e-08"/>
      <!-- Part lamp_base -->
      <geom type="mesh" class="visual" pos="-0.0042 -0.01025 0" quat="0.707107 0 -9.53114e-17 -0.707107" mesh="lamp_base" material="lamp_base_material"/>
      <geom type="mesh" class="collision" pos="-0.0042 -0.01025 0" quat="0.707107 0 -9.53114e-17 -0.707107" mesh="lamp_base" material="lamp_base_material"/>
    </body>
  </worldbody>
  <asset>
    <mesh file="lamparm__base_elbow.stl"/>
    <mesh file="zk_122.stl"/>
    <mesh file="ge_27.stl"/>
    <mesh file="pcb_chazuo_92.stl"/>
    <mesh file="金属舵盘_从动__v2.stl"/>
    <mesh file="金属舵盘_驱动__v2.stl"/>
    <mesh file="lamparm__wrist_head.stl"/>
    <mesh file="lamphead.stl"/>
    <mesh file="motor_1723_3.stl"/>
    <mesh file="sg_ziji_15.stl"/>
    <mesh file="lamp_base.stl"/>
    <mesh file="xg_ziji_16.stl"/>
    <mesh file="lamparm__elbow_wrist.stl"/>
    <material name="lamparm__base_elbow_material" rgba="0.301961 0.301961 0.301961 1"/>
    <material name="金属舵盘_驱动__v2_material" rgba="0.960784 0.960784 0.964706 1"/>
    <material name="金属舵盘_从动__v2_material" rgba="0.960784 0.960784 0.964706 1"/>
    <material name="pcb_chazuo_92_material" rgba="0.0980392 0.0980392 0.0980392 1"/>
    <material name="xg_ziji_16_material" rgba="0.0980392 0.0980392 0.0980392 1"/>
    <material name="ge_27_material" rgba="0.0980392 0.0980392 0.0980392 1"/>
    <material name="sg_ziji_15_material" rgba="0.0980392 0.0980392 0.0980392 1"/>
    <material name="zk_122_material" rgba="0.0980392 0.0980392 0.0980392 1"/>
    <material name="motor_1723_3_material" rgba="0.0980392 0.0980392 0.0980392 1"/>
    <material name="lamparm__wrist_head_material" rgba="0.301961 0.301961 0.301961 1"/>
    <material name="lamparm__elbow_wrist_material" rgba="0.301961 0.301961 0.301961 1"/>
    <material name="lamphead_material" rgba="0.301961 0.301961 0.301961 1"/>
    <material name="lamp_base_material" rgba="0.301961 0.301961 0.301961 1"/>
  </asset>
  <actuator>
    <position class="sts3215" name="2" joint="2" inheritrange="1"/>
    <position class="sts3215" name="1" joint="1" inheritrange="1"/>
    <position class="sts3215" name="3" joint="3" inheritrange="1"/>
    <position class="sts3215" name="4" joint="4" inheritrange="1"/>
    <position class="sts3215" name="5" joint="5" inheritrange="1"/>
  </actuator>
  <equality/>
</mujoco>
