<?xml version="1.0" ?>
<!-- Generated using onshape-to-robot -->
<!-- Onshape document_id: 16c9706360b5ad34f9c8db49 -->
<robot name="simulation">
  <!-- Link lamparm__base_elbow -->
  <link name="lamparm__base_elbow">
    <inertial>
      <origin xyz="-0.0229181 0.00297443 0.185358" rpy="0 0 0"/>
      <mass value="0.134549"/>
      <inertia ixx="0.000472889" ixy="1.27811e-05" ixz="0.000145734" iyy="0.000498762" iyz="-5.93489e-05" izz="8.10272e-05"/>
    </inertial>
    <!-- Part lamparm__base_elbow -->
    <visual>
      <origin xyz="-0.0201675 0.024048 0.201642" rpy="-6.775e-16 0.361044 2.75924"/>
      <geometry>
        <mesh filename="package://assets/lamparm__base_elbow.stl"/>
      </geometry>
      <material name="lamparm__base_elbow_material">
        <color rgba="0.301961 0.301961 0.301961 1"/>
      </material>
    </visual>
    <collision>
      <origin xyz="-0.0201675 0.024048 0.201642" rpy="-6.775e-16 0.361044 2.75924"/>
      <geometry>
        <mesh filename="package://assets/lamparm__base_elbow.stl"/>
      </geometry>
    </collision>
  </link>
  <!-- Link scs215_v5 -->
  <link name="scs215_v5">
    <inertial>
      <origin xyz="0.0180556 0.000605864 -0.0197123" rpy="0 0 0"/>
      <mass value="0.0852562"/>
      <inertia ixx="8.7923e-06" ixy="-3.86833e-07" ixz="9.72694e-07" iyy="1.82503e-05" iyz="6.73016e-08" izz="1.4956e-05"/>
    </inertial>
    <!-- Part 金属舵盘_驱动__v2 -->
    <visual>
      <origin xyz="-0.01 0 -0.027" rpy="1.5708 -0 4.93038e-31"/>
      <geometry>
        <mesh filename="package://assets/金属舵盘_驱动__v2.stl"/>
      </geometry>
      <material name="金属舵盘_驱动__v2_material">
        <color rgba="0.960784 0.960784 0.964706 1"/>
      </material>
    </visual>
    <collision>
      <origin xyz="-0.01 0 -0.027" rpy="1.5708 -0 4.93038e-31"/>
      <geometry>
        <mesh filename="package://assets/金属舵盘_驱动__v2.stl"/>
      </geometry>
    </collision>
    <!-- Part 金属舵盘_从动__v2 -->
    <visual>
      <origin xyz="0.01 -4.63171e-16 -0.05905" rpy="-1.5708 7.16062e-15 -3.14159"/>
      <geometry>
        <mesh filename="package://assets/金属舵盘_从动__v2.stl"/>
      </geometry>
      <material name="金属舵盘_从动__v2_material">
        <color rgba="0.960784 0.960784 0.964706 1"/>
      </material>
    </visual>
    <collision>
      <origin xyz="0.01 -4.63171e-16 -0.05905" rpy="-1.5708 7.16062e-15 -3.14159"/>
      <geometry>
        <mesh filename="package://assets/金属舵盘_从动__v2.stl"/>
      </geometry>
    </collision>
    <!-- Part pcb_chazuo_92 -->
    <visual>
      <origin xyz="0.0255 6.59195e-17 -0.0096" rpy="1.5708 -0 4.93038e-31"/>
      <geometry>
        <mesh filename="package://assets/pcb_chazuo_92.stl"/>
      </geometry>
      <material name="pcb_chazuo_92_material">
        <color rgba="0.0980392 0.0980392 0.0980392 1"/>
      </material>
    </visual>
    <collision>
      <origin xyz="0.0255 6.59195e-17 -0.0096" rpy="1.5708 -0 4.93038e-31"/>
      <geometry>
        <mesh filename="package://assets/pcb_chazuo_92.stl"/>
      </geometry>
    </collision>
    <!-- Part xg_ziji_16 -->
    <visual>
      <origin xyz="0.0255 6.59195e-17 -0.0096" rpy="1.5708 -0 4.93038e-31"/>
      <geometry>
        <mesh filename="package://assets/xg_ziji_16.stl"/>
      </geometry>
      <material name="xg_ziji_16_material">
        <color rgba="0.0980392 0.0980392 0.0980392 1"/>
      </material>
    </visual>
    <collision>
      <origin xyz="0.0255 6.59195e-17 -0.0096" rpy="1.5708 -0 4.93038e-31"/>
      <geometry>
        <mesh filename="package://assets/xg_ziji_16.stl"/>
      </geometry>
    </collision>
    <!-- Part ge_27 -->
    <visual>
      <origin xyz="-1.249e-16 6.93889e-17 -0.0156" rpy="-3.14159 -0 4.93038e-31"/>
      <geometry>
        <mesh filename="package://assets/ge_27.stl"/>
      </geometry>
      <material name="ge_27_material">
        <color rgba="0.0980392 0.0980392 0.0980392 1"/>
      </material>
    </visual>
    <collision>
      <origin xyz="-1.249e-16 6.93889e-17 -0.0156" rpy="-3.14159 -0 4.93038e-31"/>
      <geometry>
        <mesh filename="package://assets/ge_27.stl"/>
      </geometry>
    </collision>
    <!-- Part sg_ziji_15 -->
    <visual>
      <origin xyz="0.0255 6.59195e-17 -0.0096" rpy="1.5708 -0 4.93038e-31"/>
      <geometry>
        <mesh filename="package://assets/sg_ziji_15.stl"/>
      </geometry>
      <material name="sg_ziji_15_material">
        <color rgba="0.0980392 0.0980392 0.0980392 1"/>
      </material>
    </visual>
    <collision>
      <origin xyz="0.0255 6.59195e-17 -0.0096" rpy="1.5708 -0 4.93038e-31"/>
      <geometry>
        <mesh filename="package://assets/sg_ziji_15.stl"/>
      </geometry>
    </collision>
    <!-- Part zk_122 -->
    <visual>
      <origin xyz="0.0255 6.59195e-17 -0.0096" rpy="1.5708 -0 4.93038e-31"/>
      <geometry>
        <mesh filename="package://assets/zk_122.stl"/>
      </geometry>
      <material name="zk_122_material">
        <color rgba="0.0980392 0.0980392 0.0980392 1"/>
      </material>
    </visual>
    <collision>
      <origin xyz="0.0255 6.59195e-17 -0.0096" rpy="1.5708 -0 4.93038e-31"/>
      <geometry>
        <mesh filename="package://assets/zk_122.stl"/>
      </geometry>
    </collision>
    <!-- Part motor_1723_3 -->
    <visual>
      <origin xyz="0.0255 0.00125 -0.03245" rpy="1.5708 -5.55112e-17 1.5708"/>
      <geometry>
        <mesh filename="package://assets/motor_1723_3.stl"/>
      </geometry>
      <material name="motor_1723_3_material">
        <color rgba="0.0980392 0.0980392 0.0980392 1"/>
      </material>
    </visual>
    <collision>
      <origin xyz="0.0255 0.00125 -0.03245" rpy="1.5708 -5.55112e-17 1.5708"/>
      <geometry>
        <mesh filename="package://assets/motor_1723_3.stl"/>
      </geometry>
    </collision>
  </link>
  <!-- Joint from lamparm__base_elbow to scs215_v5 -->
  <joint name="2" type="revolute">
    <origin xyz="0.0154636 0.00756357 0.08031" rpy="-1.18845 1.5708 0"/>
    <parent link="lamparm__base_elbow"/>
    <child link="scs215_v5"/>
    <axis xyz="0 0 1"/>
    <limit effort="10" velocity="10" lower="-1.93184" upper="1.20975"/>
  </joint>
  <!-- Additional sensors.xml -->
  <sensor>
    <accelerometer name="accel_sensor" site="imu_site"/>
    <gyro name="gyro_sensor" site="imu_site"/>
  </sensor>
  <!-- Additional joints_properties.xml -->
  <default>
    <default class="sts3215">
      <geom contype="0" conaffinity="0"/>
      <joint damping="0.60" frictionloss="0.052" armature="0.028"/>
      <position kp="17.8" kv="0.0" forcerange="-3.35 3.35"/>
    </default>
    <default class="backlash">
      <!-- +/- 0.5° of backlash -->
      <joint damping="0.01" frictionloss="0" armature="0.01" limited="true" range="-0.008726646259971648 0.008726646259971648"/>
    </default>
  </default>
</robot>
