<?xml version="1.0" ?>
<!-- Generated using onshape-to-robot -->
<!-- Onshape document_id: 7ff6d1fd85a1383ea9f71557 -->
<mujoco model="lelamp">
  <compiler angle="radian" meshdir="assets" autolimits="true"/>
  <default>
    <default class="lelamp">
      <joint frictionloss="0.1" armature="0.005"/>
      <position kp="50" dampratio="1"/>
      <default class="visual">
        <geom type="mesh" contype="0" conaffinity="0" group="2"/>
      </default>
      <default class="collision">
        <geom group="3"/>
      </default>
    </default>
  </default>
  <!-- Additional sensors.xml -->
  <sensor>
    <accelerometer name="accel_sensor" site="imu_site"/>
    <gyro name="gyro_sensor" site="imu_site"/>
  </sensor>
  <!-- Additional joints_properties.xml -->
  <default>
    <default class="sts3215">
      <geom contype="0" conaffinity="0"/>
      <joint damping="0.60" frictionloss="0.052" armature="0.028"/>
      <position kp="17.8" kv="0.0" forcerange="-3.35 3.35"/>
    </default>
    <default class="backlash">
      <!-- +/- 0.5° of backlash -->
      <joint damping="0.01" frictionloss="0" armature="0.01" limited="true" range="-0.008726646259971648 0.008726646259971648"/>
    </default>
  </default>
  <worldbody>
    <!-- Link dc15_a01_dummy_assy_idle_asm -->
    <body name="dc15_a01_dummy_assy_idle_asm" pos="0 0 0" quat="1 0 0 0" childclass="lelamp">
      <site name="imu_site" pos="0 0 0" />
      <freejoint name="dc15_a01_dummy_assy_idle_asm_freejoint"/>
      <inertial pos="-1.88967e-06 0.00732928 0.00959762" mass="0.140913" fullinertia="9.08799e-05 8.05617e-05 0.000163373 1.81155e-09 1.89009e-09 1.28621e-07"/>
      <!-- Part base -->
      <geom type="mesh" class="visual" pos="0 0.0075 0.001" quat="1 0 -2.77556e-16 -0" mesh="base" material="base_material"/>
      <geom type="mesh" class="collision" pos="0 0.0075 0.001" quat="1 0 -2.77556e-16 -0" mesh="base" material="base_material"/>
      <!-- Part dc15_a01_led_cap2_dummy -->
      <geom type="mesh" class="visual" pos="1.73472e-18 -0.0075 0.0049" quat="0 1 0 0" mesh="dc15_a01_led_cap2_dummy" material="dc15_a01_led_cap2_dummy_material"/>
      <geom type="mesh" class="collision" pos="1.73472e-18 -0.0075 0.0049" quat="0 1 0 0" mesh="dc15_a01_led_cap2_dummy" material="dc15_a01_led_cap2_dummy_material"/>
      <!-- Part bts2_m2_6x8 -->
      <geom type="mesh" class="visual" pos="0 0 0.0274" quat="0.707107 0.707107 -0 -1.24062e-30" mesh="bts2_m2_6x8" material="bts2_m2_6x8_material"/>
      <geom type="mesh" class="collision" pos="0 0 0.0274" quat="0.707107 0.707107 -0 -1.24062e-30" mesh="bts2_m2_6x8" material="bts2_m2_6x8_material"/>
      <!-- Part b3b_eh -->
      <geom type="mesh" class="visual" pos="0.0077 0.009 0.0121" quat="0.5 -0.5 0.5 -0.5" mesh="b3b_eh" material="b3b_eh_material"/>
      <geom type="mesh" class="collision" pos="0.0077 0.009 0.0121" quat="0.5 -0.5 0.5 -0.5" mesh="b3b_eh" material="b3b_eh_material"/>
      <!-- Part b3b_eh_2 -->
      <geom type="mesh" class="visual" pos="-0.0077 0.009 0.0121" quat="0.5 -0.5 -0.5 0.5" mesh="b3b_eh" material="b3b_eh_material"/>
      <geom type="mesh" class="collision" pos="-0.0077 0.009 0.0121" quat="0.5 -0.5 -0.5 0.5" mesh="b3b_eh" material="b3b_eh_material"/>
      <!-- Part dc15_a01_case_m_dummy -->
      <geom type="mesh" class="visual" pos="1.73472e-18 -1.73472e-18 0.0225" quat="0 0 0 1" mesh="dc15_a01_case_m_dummy" material="dc15_a01_case_m_dummy_material"/>
      <geom type="mesh" class="collision" pos="1.73472e-18 -1.73472e-18 0.0225" quat="0 0 0 1" mesh="dc15_a01_case_m_dummy" material="dc15_a01_case_m_dummy_material"/>
      <!-- Part bts2_m2_6x8_2 -->
      <geom type="mesh" class="visual" pos="0 0 0.0018" quat="0 -0 -0.707107 0.707107" mesh="bts2_m2_6x8" material="bts2_m2_6x8_material"/>
      <geom type="mesh" class="collision" pos="0 0 0.0018" quat="0 -0 -0.707107 0.707107" mesh="bts2_m2_6x8" material="bts2_m2_6x8_material"/>
      <!-- Part dc15_a01_horn_dummy -->
      <geom type="mesh" class="visual" pos="0 -1.73472e-18 0.0261" quat="0.707107 0.707107 -0 -1.24062e-30" mesh="dc15_a01_horn_dummy" material="dc15_a01_horn_dummy_material"/>
      <geom type="mesh" class="collision" pos="0 -1.73472e-18 0.0261" quat="0.707107 0.707107 -0 -1.24062e-30" mesh="dc15_a01_horn_dummy" material="dc15_a01_horn_dummy_material"/>
      <!-- Part dc15_a01_case_f_dummy -->
      <geom type="mesh" class="visual" pos="1.73472e-18 -1.73472e-18 0.0225" quat="0 0 0 1" mesh="dc15_a01_case_f_dummy" material="dc15_a01_case_f_dummy_material"/>
      <geom type="mesh" class="collision" pos="1.73472e-18 -1.73472e-18 0.0225" quat="0 0 0 1" mesh="dc15_a01_case_f_dummy" material="dc15_a01_case_f_dummy_material"/>
      <!-- Part dc15_a01_case_b_dummy -->
      <geom type="mesh" class="visual" pos="0 -3.46945e-18 0.003" quat="0 0 0 1" mesh="dc15_a01_case_b_dummy" material="dc15_a01_case_b_dummy_material"/>
      <geom type="mesh" class="collision" pos="0 -3.46945e-18 0.003" quat="0 0 0 1" mesh="dc15_a01_case_b_dummy" material="dc15_a01_case_b_dummy_material"/>
      <!-- Part dc15_a01_horn_idle2_dummy -->
      <geom type="mesh" class="visual" pos="0 0 0.0029" quat="4.79291e-19 0 -1 -1.11022e-16" mesh="dc15_a01_horn_idle2_dummy" material="dc15_a01_horn_idle2_dummy_material"/>
      <geom type="mesh" class="collision" pos="0 0 0.0029" quat="4.79291e-19 0 -1 -1.11022e-16" mesh="dc15_a01_horn_idle2_dummy" material="dc15_a01_horn_idle2_dummy_material"/>
      <!-- Part dc15_a01_idle_cap_dummy -->
      <geom type="mesh" class="visual" pos="0 0 0.0002" quat="0 -0 -0.707107 0.707107" mesh="dc15_a01_idle_cap_dummy" material="dc15_a01_idle_cap_dummy_material"/>
      <geom type="mesh" class="collision" pos="0 0 0.0002" quat="0 -0 -0.707107 0.707107" mesh="dc15_a01_idle_cap_dummy" material="dc15_a01_idle_cap_dummy_material"/>
      <!-- Link square_joint -->
      <body name="square_joint" pos="4.75779e-29 -1.73472e-18 0.0288" quat="0.444744 0 0 -0.895658">
        <!-- Joint from dc15_a01_dummy_assy_idle_asm to square_joint -->
        <joint axis="0 0 1" name="1" type="hinge" range="-4.063370492512279 2.2198148146673073" class="sts3215"/>
        <inertial pos="-8.75044e-06 -0.000538186 0.0283784" mass="0.0304303" fullinertia="6.68219e-06 6.31947e-06 3.33001e-06 6.6143e-10 -1.534e-09 -1.78501e-07"/>
        <!-- Part square_joint -->
        <geom type="mesh" class="visual" pos="-1.92593e-34 -1.92593e-34 0" quat="1 -0 2.34507e-19 2.74968e-38" mesh="square_joint" material="square_joint_material"/>
        <geom type="mesh" class="collision" pos="-1.92593e-34 -1.92593e-34 0" quat="1 -0 2.34507e-19 2.74968e-38" mesh="square_joint" material="square_joint_material"/>
        <!-- Part dc15_a01_led_cap2_dummy_2 -->
        <geom type="mesh" class="visual" pos="2.10937e-16 -0.00985 0.04425" quat="0.707107 0.707107 2.22045e-16 -5.83644e-16" mesh="dc15_a01_led_cap2_dummy" material="dc15_a01_led_cap2_dummy_material"/>
        <geom type="mesh" class="collision" pos="2.10937e-16 -0.00985 0.04425" quat="0.707107 0.707107 2.22045e-16 -5.83644e-16" mesh="dc15_a01_led_cap2_dummy" material="dc15_a01_led_cap2_dummy_material"/>
        <!-- Part bts2_m2_6x8_3 -->
        <geom type="mesh" class="visual" pos="3.13823e-15 0.01265 0.03675" quat="1 3.91857e-16 6.66134e-16 1.67497e-16" mesh="bts2_m2_6x8" material="bts2_m2_6x8_material"/>
        <geom type="mesh" class="collision" pos="3.13823e-15 0.01265 0.03675" quat="1 3.91857e-16 6.66134e-16 1.67497e-16" mesh="bts2_m2_6x8" material="bts2_m2_6x8_material"/>
        <!-- Part b3b_eh_3 -->
        <geom type="mesh" class="visual" pos="0.0077 -0.00265 0.02775" quat="5.0358e-16 -0.707107 5.55112e-16 -0.707107" mesh="b3b_eh" material="b3b_eh_material"/>
        <geom type="mesh" class="collision" pos="0.0077 -0.00265 0.02775" quat="5.0358e-16 -0.707107 5.55112e-16 -0.707107" mesh="b3b_eh" material="b3b_eh_material"/>
        <!-- Part b3b_eh_4 -->
        <geom type="mesh" class="visual" pos="-0.0077 -0.00265 0.02775" quat="3.58633e-16 -0.707107 -3.33067e-16 0.707107" mesh="b3b_eh" material="b3b_eh_material"/>
        <geom type="mesh" class="collision" pos="-0.0077 -0.00265 0.02775" quat="3.58633e-16 -0.707107 -3.33067e-16 0.707107" mesh="b3b_eh" material="b3b_eh_material"/>
        <!-- Part dc15_a01_case_m_dummy_2 -->
        <geom type="mesh" class="visual" pos="2.48922e-15 0.00775 0.03675" quat="0 -1.90985e-16 -0.707107 -0.707107" mesh="dc15_a01_case_m_dummy" material="dc15_a01_case_m_dummy_material"/>
        <geom type="mesh" class="collision" pos="2.48922e-15 0.00775 0.03675" quat="0 -1.90985e-16 -0.707107 -0.707107" mesh="dc15_a01_case_m_dummy" material="dc15_a01_case_m_dummy_material"/>
        <!-- Part bts2_m2_6x8_4 -->
        <geom type="mesh" class="visual" pos="-1.98942e-16 -0.01295 0.03675" quat="1.23511e-13 5.82867e-16 -0 1" mesh="bts2_m2_6x8" material="bts2_m2_6x8_material"/>
        <geom type="mesh" class="collision" pos="-1.98942e-16 -0.01295 0.03675" quat="1.23511e-13 5.82867e-16 -0 1" mesh="bts2_m2_6x8" material="bts2_m2_6x8_material"/>
        <!-- Part dc15_a01_horn_dummy_2 -->
        <geom type="mesh" class="visual" pos="2.95961e-15 0.01135 0.03675" quat="1 3.91857e-16 6.66134e-16 1.67497e-16" mesh="dc15_a01_horn_dummy" material="dc15_a01_horn_dummy_material"/>
        <geom type="mesh" class="collision" pos="2.95961e-15 0.01135 0.03675" quat="1 3.91857e-16 6.66134e-16 1.67497e-16" mesh="dc15_a01_horn_dummy" material="dc15_a01_horn_dummy_material"/>
        <!-- Part dc15_a01_case_f_dummy_2 -->
        <geom type="mesh" class="visual" pos="2.48922e-15 0.00775 0.03675" quat="0 -1.90985e-16 -0.707107 -0.707107" mesh="dc15_a01_case_f_dummy" material="dc15_a01_case_f_dummy_material"/>
        <geom type="mesh" class="collision" pos="2.48922e-15 0.00775 0.03675" quat="0 -1.90985e-16 -0.707107 -0.707107" mesh="dc15_a01_case_f_dummy" material="dc15_a01_case_f_dummy_material"/>
        <!-- Part dc15_a01_case_b_dummy_2 -->
        <geom type="mesh" class="visual" pos="-2.43083e-17 -0.01175 0.03675" quat="0 -1.90985e-16 -0.707107 -0.707107" mesh="dc15_a01_case_b_dummy" material="dc15_a01_case_b_dummy_material"/>
        <geom type="mesh" class="collision" pos="-2.43083e-17 -0.01175 0.03675" quat="0 -1.90985e-16 -0.707107 -0.707107" mesh="dc15_a01_case_b_dummy" material="dc15_a01_case_b_dummy_material"/>
        <!-- Part dc15_a01_horn_idle2_dummy_2 -->
        <geom type="mesh" class="visual" pos="-1.01745e-17 -0.01185 0.03675" quat="6.66134e-16 5.14171e-16 -0.707107 0.707107" mesh="dc15_a01_horn_idle2_dummy" material="dc15_a01_horn_idle2_dummy_material"/>
        <geom type="mesh" class="collision" pos="-1.01745e-17 -0.01185 0.03675" quat="6.66134e-16 5.14171e-16 -0.707107 0.707107" mesh="dc15_a01_horn_idle2_dummy" material="dc15_a01_horn_idle2_dummy_material"/>
        <!-- Part dc15_a01_idle_cap_dummy_2 -->
        <geom type="mesh" class="visual" pos="-4.14788e-16 -0.01455 0.03675" quat="1.23511e-13 5.82867e-16 -0 1" mesh="dc15_a01_idle_cap_dummy" material="dc15_a01_idle_cap_dummy_material"/>
        <geom type="mesh" class="collision" pos="-4.14788e-16 -0.01455 0.03675" quat="1.23511e-13 5.82867e-16 -0 1" mesh="dc15_a01_idle_cap_dummy" material="dc15_a01_idle_cap_dummy_material"/>
        <!-- Link dc15_a01_dummy_assy_idle_asm_2 -->
        <body name="dc15_a01_dummy_assy_idle_asm_2" pos="2.95779e-15 0.01405 0.03675" quat="0.707107 -0.707107 3.33067e-16 5.83302e-16">
          <!-- Joint from square_joint to dc15_a01_dummy_assy_idle_asm_2 -->
          <joint axis="0 0 1" name="2" type="hinge" range="-2.4943173274451675 1.3454070269423575" class="sts3215"/>
          <inertial pos="0.0822208 -0.126814 -0.0137912" mass="0.0439213" fullinertia="0.000137751 6.04949e-05 0.000192616 8.65848e-05 -5.06943e-07 7.78758e-07"/>
          <!-- Part arm_length_15cm -->
          <geom type="mesh" class="visual" pos="-6.68316e-18 1.38778e-17 0.002" quat="4.39562e-16 0.959033 0.283294 3.04226e-15" mesh="arm_length_15cm" material="arm_length_15cm_material"/>
          <geom type="mesh" class="collision" pos="-6.68316e-18 1.38778e-17 0.002" quat="4.39562e-16 0.959033 0.283294 3.04226e-15" mesh="arm_length_15cm" material="arm_length_15cm_material"/>
          <!-- Part dc15_a01_led_cap2_dummy_3 -->
          <geom type="mesh" class="visual" pos="0.112553 -0.173428 -0.0231" quat="4.07021e-14 -0.959033 -0.283294 3.72267e-14" mesh="dc15_a01_led_cap2_dummy" material="dc15_a01_led_cap2_dummy_material"/>
          <geom type="mesh" class="collision" pos="0.112553 -0.173428 -0.0231" quat="4.07021e-14 -0.959033 -0.283294 3.72267e-14" mesh="dc15_a01_led_cap2_dummy" material="dc15_a01_led_cap2_dummy_material"/>
          <!-- Part bts2_m2_6x8_5 -->
          <geom type="mesh" class="visual" pos="0.108478 -0.167132 -0.0006" quat="0.678139 0.678139 0.200319 0.200319" mesh="bts2_m2_6x8" material="bts2_m2_6x8_material"/>
          <geom type="mesh" class="collision" pos="0.108478 -0.167132 -0.0006" quat="0.678139 0.678139 0.200319 0.200319" mesh="bts2_m2_6x8" material="bts2_m2_6x8_material"/>
          <!-- Part b3b_eh_5 -->
          <geom type="mesh" class="visual" pos="0.110051 -0.155393 -0.0159" quat="0.621164 -0.621164 0.337869 -0.337869" mesh="b3b_eh" material="b3b_eh_material"/>
          <geom type="mesh" class="collision" pos="0.110051 -0.155393 -0.0159" quat="0.621164 -0.621164 0.337869 -0.337869" mesh="b3b_eh" material="b3b_eh_material"/>
          <!-- Part b3b_eh_6 -->
          <geom type="mesh" class="visual" pos="0.0971234 -0.163761 -0.0159" quat="0.337869 -0.337869 -0.621164 0.621164" mesh="b3b_eh" material="b3b_eh_material"/>
          <geom type="mesh" class="collision" pos="0.0971234 -0.163761 -0.0159" quat="0.337869 -0.337869 -0.621164 0.621164" mesh="b3b_eh" material="b3b_eh_material"/>
          <!-- Part dc15_a01_case_m_dummy_3 -->
          <geom type="mesh" class="visual" pos="0.108478 -0.167132 -0.0055" quat="0.283294 1.03332e-15 -8.88178e-16 -0.959033" mesh="dc15_a01_case_m_dummy" material="dc15_a01_case_m_dummy_material"/>
          <geom type="mesh" class="collision" pos="0.108478 -0.167132 -0.0055" quat="0.283294 1.03332e-15 -8.88178e-16 -0.959033" mesh="dc15_a01_case_m_dummy" material="dc15_a01_case_m_dummy_material"/>
          <!-- Part bts2_m2_6x8_6 -->
          <geom type="mesh" class="visual" pos="0.108478 -0.167132 -0.0262" quat="0.200319 -0.200319 0.678139 -0.678139" mesh="bts2_m2_6x8" material="bts2_m2_6x8_material"/>
          <geom type="mesh" class="collision" pos="0.108478 -0.167132 -0.0262" quat="0.200319 -0.200319 0.678139 -0.678139" mesh="bts2_m2_6x8" material="bts2_m2_6x8_material"/>
          <!-- Part dc15_a01_horn_dummy_3 -->
          <geom type="mesh" class="visual" pos="0.108478 -0.167132 -0.0019" quat="0.678139 0.678139 0.200319 0.200319" mesh="dc15_a01_horn_dummy" material="dc15_a01_horn_dummy_material"/>
          <geom type="mesh" class="collision" pos="0.108478 -0.167132 -0.0019" quat="0.678139 0.678139 0.200319 0.200319" mesh="dc15_a01_horn_dummy" material="dc15_a01_horn_dummy_material"/>
          <!-- Part dc15_a01_case_f_dummy_3 -->
          <geom type="mesh" class="visual" pos="0.108478 -0.167132 -0.0055" quat="0.283294 1.03332e-15 -8.88178e-16 -0.959033" mesh="dc15_a01_case_f_dummy" material="dc15_a01_case_f_dummy_material"/>
          <geom type="mesh" class="collision" pos="0.108478 -0.167132 -0.0055" quat="0.283294 1.03332e-15 -8.88178e-16 -0.959033" mesh="dc15_a01_case_f_dummy" material="dc15_a01_case_f_dummy_material"/>
          <!-- Part dc15_a01_case_b_dummy_3 -->
          <geom type="mesh" class="visual" pos="0.108478 -0.167132 -0.025" quat="0.283294 1.03332e-15 -8.88178e-16 -0.959033" mesh="dc15_a01_case_b_dummy" material="dc15_a01_case_b_dummy_material"/>
          <geom type="mesh" class="collision" pos="0.108478 -0.167132 -0.025" quat="0.283294 1.03332e-15 -8.88178e-16 -0.959033" mesh="dc15_a01_case_b_dummy" material="dc15_a01_case_b_dummy_material"/>
          <!-- Part dc15_a01_horn_idle2_dummy_3 -->
          <geom type="mesh" class="visual" pos="0.108478 -0.167132 -0.0251" quat="3.89445e-16 0.283294 -0.959033 -1.73688e-14" mesh="dc15_a01_horn_idle2_dummy" material="dc15_a01_horn_idle2_dummy_material"/>
          <geom type="mesh" class="collision" pos="0.108478 -0.167132 -0.0251" quat="3.89445e-16 0.283294 -0.959033 -1.73688e-14" mesh="dc15_a01_horn_idle2_dummy" material="dc15_a01_horn_idle2_dummy_material"/>
          <!-- Part dc15_a01_idle_cap_dummy_3 -->
          <geom type="mesh" class="visual" pos="0.108478 -0.167132 -0.0278" quat="0.200319 -0.200319 0.678139 -0.678139" mesh="dc15_a01_idle_cap_dummy" material="dc15_a01_idle_cap_dummy_material"/>
          <geom type="mesh" class="collision" pos="0.108478 -0.167132 -0.0278" quat="0.200319 -0.200319 0.678139 -0.678139" mesh="dc15_a01_idle_cap_dummy" material="dc15_a01_idle_cap_dummy_material"/>
          <!-- Link arm_length_10cm -->
          <body name="arm_length_10cm" pos="0.108478 -0.167132 0.0008" quat="0.720403 -1.01825e-14 -2.27596e-14 -0.693556">
            <!-- Joint from dc15_a01_dummy_assy_idle_asm_2 to arm_length_10cm -->
            <joint axis="0 0 1" name="3" type="hinge" range="-1.3833767485832635 2.4563476058042615" class="sts3215"/>
            <inertial pos="0.000125498 -0.115742 -0.013751" mass="0.040387" fullinertia="9.51594e-05 4.19848e-06 9.39396e-05 1.396e-07 -2.20999e-09 6.104e-07"/>
            <!-- Part arm_length_10cm -->
            <geom type="mesh" class="visual" pos="0 1.38778e-17 0.002" quat="0 1 0 0" mesh="arm_length_10cm" material="arm_length_10cm_material"/>
            <geom type="mesh" class="collision" pos="0 1.38778e-17 0.002" quat="0 1 0 0" mesh="arm_length_10cm" material="arm_length_10cm_material"/>
            <!-- Part dc15_a01_led_cap2_dummy_4 -->
            <geom type="mesh" class="visual" pos="0.00025 -0.15675 -0.0231" quat="8.1003e-16 1 1.23092e-14 -1.55289e-14" mesh="dc15_a01_led_cap2_dummy" material="dc15_a01_led_cap2_dummy_material"/>
            <geom type="mesh" class="collision" pos="0.00025 -0.15675 -0.0231" quat="8.1003e-16 1 1.23092e-14 -1.55289e-14" mesh="dc15_a01_led_cap2_dummy" material="dc15_a01_led_cap2_dummy_material"/>
            <!-- Part bts2_m2_6x8_7 -->
            <geom type="mesh" class="visual" pos="0.00025 -0.14925 -0.0006" quat="0.707107 0.707107 3.64153e-14 3.84984e-15" mesh="bts2_m2_6x8" material="bts2_m2_6x8_material"/>
            <geom type="mesh" class="collision" pos="0.00025 -0.14925 -0.0006" quat="0.707107 0.707107 3.64153e-14 3.84984e-15" mesh="bts2_m2_6x8" material="bts2_m2_6x8_material"/>
            <!-- Part b3b_eh_7 -->
            <geom type="mesh" class="visual" pos="0.00795 -0.14025 -0.0159" quat="0.5 -0.5 0.5 -0.5" mesh="b3b_eh" material="b3b_eh_material"/>
            <geom type="mesh" class="collision" pos="0.00795 -0.14025 -0.0159" quat="0.5 -0.5 0.5 -0.5" mesh="b3b_eh" material="b3b_eh_material"/>
            <!-- Part b3b_eh_8 -->
            <geom type="mesh" class="visual" pos="-0.00745 -0.14025 -0.0159" quat="0.5 -0.5 -0.5 0.5" mesh="b3b_eh" material="b3b_eh_material"/>
            <geom type="mesh" class="collision" pos="-0.00745 -0.14025 -0.0159" quat="0.5 -0.5 -0.5 0.5" mesh="b3b_eh" material="b3b_eh_material"/>
            <!-- Part dc15_a01_case_m_dummy_4 -->
            <geom type="mesh" class="visual" pos="0.00025 -0.14925 -0.0055" quat="2.28983e-15 -7.15001e-17 -1.39125e-15 1" mesh="dc15_a01_case_m_dummy" material="dc15_a01_case_m_dummy_material"/>
            <geom type="mesh" class="collision" pos="0.00025 -0.14925 -0.0055" quat="2.28983e-15 -7.15001e-17 -1.39125e-15 1" mesh="dc15_a01_case_m_dummy" material="dc15_a01_case_m_dummy_material"/>
            <!-- Part bts2_m2_6x8_8 -->
            <geom type="mesh" class="visual" pos="0.00025 -0.14925 -0.0262" quat="2.7367e-14 -2.25334e-14 0.707107 -0.707107" mesh="bts2_m2_6x8" material="bts2_m2_6x8_material"/>
            <geom type="mesh" class="collision" pos="0.00025 -0.14925 -0.0262" quat="2.7367e-14 -2.25334e-14 0.707107 -0.707107" mesh="bts2_m2_6x8" material="bts2_m2_6x8_material"/>
            <!-- Part dc15_a01_horn_dummy_4 -->
            <geom type="mesh" class="visual" pos="0.00025 -0.14925 -0.0019" quat="0.707107 0.707107 3.64153e-14 3.84984e-15" mesh="dc15_a01_horn_dummy" material="dc15_a01_horn_dummy_material"/>
            <geom type="mesh" class="collision" pos="0.00025 -0.14925 -0.0019" quat="0.707107 0.707107 3.64153e-14 3.84984e-15" mesh="dc15_a01_horn_dummy" material="dc15_a01_horn_dummy_material"/>
            <!-- Part dc15_a01_case_f_dummy_4 -->
            <geom type="mesh" class="visual" pos="0.00025 -0.14925 -0.0055" quat="2.28983e-15 -7.15001e-17 -1.39125e-15 1" mesh="dc15_a01_case_f_dummy" material="dc15_a01_case_f_dummy_material"/>
            <geom type="mesh" class="collision" pos="0.00025 -0.14925 -0.0055" quat="2.28983e-15 -7.15001e-17 -1.39125e-15 1" mesh="dc15_a01_case_f_dummy" material="dc15_a01_case_f_dummy_material"/>
            <!-- Part dc15_a01_case_b_dummy_4 -->
            <geom type="mesh" class="visual" pos="0.00025 -0.14925 -0.025" quat="2.28983e-15 -7.15001e-17 -1.39125e-15 1" mesh="dc15_a01_case_b_dummy" material="dc15_a01_case_b_dummy_material"/>
            <geom type="mesh" class="collision" pos="0.00025 -0.14925 -0.025" quat="2.28983e-15 -7.15001e-17 -1.39125e-15 1" mesh="dc15_a01_case_b_dummy" material="dc15_a01_case_b_dummy_material"/>
            <!-- Part dc15_a01_horn_idle2_dummy_4 -->
            <geom type="mesh" class="visual" pos="0.00025 -0.14925 -0.0251" quat="2.46331e-15 -4.04398e-14 1 2.93038e-15" mesh="dc15_a01_horn_idle2_dummy" material="dc15_a01_horn_idle2_dummy_material"/>
            <geom type="mesh" class="collision" pos="0.00025 -0.14925 -0.0251" quat="2.46331e-15 -4.04398e-14 1 2.93038e-15" mesh="dc15_a01_horn_idle2_dummy" material="dc15_a01_horn_idle2_dummy_material"/>
            <!-- Part dc15_a01_idle_cap_dummy_4 -->
            <geom type="mesh" class="visual" pos="0.00025 -0.14925 -0.0278" quat="2.7367e-14 -2.25334e-14 0.707107 -0.707107" mesh="dc15_a01_idle_cap_dummy" material="dc15_a01_idle_cap_dummy_material"/>
            <geom type="mesh" class="collision" pos="0.00025 -0.14925 -0.0278" quat="2.7367e-14 -2.25334e-14 0.707107 -0.707107" mesh="dc15_a01_idle_cap_dummy" material="dc15_a01_idle_cap_dummy_material"/>
            <!-- Link angle_joint -->
            <body name="angle_joint" pos="0.00025 -0.14925 0.0008" quat="1 -5.13748e-15 2.30926e-14 2.84373e-14">
              <!-- Joint from arm_length_10cm to angle_joint -->
              <joint axis="0 0 1" name="4" type="hinge" range="-1.680046420324199 2.159677934063326" class="sts3215"/>
              <inertial pos="-0.00122043 -0.0302719 -0.0162582" mass="0.0271577" fullinertia="5.38249e-06 3.94214e-06 6.2876e-06 1.1386e-07 -4.06455e-09 5.13711e-09"/>
              <!-- Part angle_joint -->
              <geom type="mesh" class="visual" pos="0 6.93889e-18 0" quat="3.25635e-15 0.99282 -0.119621 -5.12971e-16" mesh="angle_joint" material="angle_joint_material"/>
              <geom type="mesh" class="collision" pos="0 6.93889e-18 0" quat="3.25635e-15 0.99282 -0.119621 -5.12971e-16" mesh="angle_joint" material="angle_joint_material"/>
              <!-- Part dc15_a01_led_cap2_dummy_5 -->
              <geom type="mesh" class="visual" pos="-0.0127787 -0.0217368 -0.01625" quat="0.55622 -0.436599 0.55622 0.436599" mesh="dc15_a01_led_cap2_dummy" material="dc15_a01_led_cap2_dummy_material"/>
              <geom type="mesh" class="collision" pos="-0.0127787 -0.0217368 -0.01625" quat="0.55622 -0.436599 0.55622 0.436599" mesh="dc15_a01_led_cap2_dummy" material="dc15_a01_led_cap2_dummy_material"/>
              <!-- Part bts2_m2_6x8_9 -->
              <geom type="mesh" class="visual" pos="-0.0108376 -0.0453743 -0.01625" quat="0.0845846 -0.70203 0.0845846 0.70203" mesh="bts2_m2_6x8" material="bts2_m2_6x8_material"/>
              <geom type="mesh" class="collision" pos="-0.0108376 -0.0453743 -0.01625" quat="0.0845846 -0.70203 0.0845846 0.70203" mesh="bts2_m2_6x8" material="bts2_m2_6x8_material"/>
              <!-- Part b3b_eh_9 -->
              <geom type="mesh" class="visual" pos="0.00153891 -0.0326499 -0.02395" quat="1.69151e-15 -0.119621 -0.99282 1.85971e-14" mesh="b3b_eh" material="b3b_eh_material"/>
              <geom type="mesh" class="collision" pos="0.00153891 -0.0326499 -0.02395" quat="1.69151e-15 -0.119621 -0.99282 1.85971e-14" mesh="b3b_eh" material="b3b_eh_material"/>
              <!-- Part b3b_eh_10 -->
              <geom type="mesh" class="visual" pos="0.00153891 -0.0326499 -0.00855" quat="0.99282 -1.85946e-14 1.9984e-15 -0.119621" mesh="b3b_eh" material="b3b_eh_material"/>
              <geom type="mesh" class="collision" pos="0.00153891 -0.0326499 -0.00855" quat="0.99282 -1.85946e-14 1.9984e-15 -0.119621" mesh="b3b_eh" material="b3b_eh_material"/>
              <!-- Part dc15_a01_case_m_dummy_5 -->
              <geom type="mesh" class="visual" pos="-0.00967377 -0.0406146 -0.01625" quat="0.55622 0.436599 -0.55622 0.436599" mesh="dc15_a01_case_m_dummy" material="dc15_a01_case_m_dummy_material"/>
              <geom type="mesh" class="collision" pos="-0.00967377 -0.0406146 -0.01625" quat="0.55622 0.436599 -0.55622 0.436599" mesh="dc15_a01_case_m_dummy" material="dc15_a01_case_m_dummy_material"/>
              <!-- Part bts2_m2_6x8_10 -->
              <geom type="mesh" class="visual" pos="-0.00475703 -0.020507 -0.01625" quat="0.70203 -0.0845846 -0.70203 -0.0845846" mesh="bts2_m2_6x8" material="bts2_m2_6x8_material"/>
              <geom type="mesh" class="collision" pos="-0.00475703 -0.020507 -0.01625" quat="0.70203 -0.0845846 -0.70203 -0.0845846" mesh="bts2_m2_6x8" material="bts2_m2_6x8_material"/>
              <!-- Part dc15_a01_horn_dummy_5 -->
              <geom type="mesh" class="visual" pos="-0.0105289 -0.0441115 -0.01625" quat="0.0845846 -0.70203 0.0845846 0.70203" mesh="dc15_a01_horn_dummy" material="dc15_a01_horn_dummy_material"/>
              <geom type="mesh" class="collision" pos="-0.0105289 -0.0441115 -0.01625" quat="0.0845846 -0.70203 0.0845846 0.70203" mesh="dc15_a01_horn_dummy" material="dc15_a01_horn_dummy_material"/>
              <!-- Part dc15_a01_case_f_dummy_5 -->
              <geom type="mesh" class="visual" pos="-0.00967377 -0.0406146 -0.01625" quat="0.55622 0.436599 -0.55622 0.436599" mesh="dc15_a01_case_f_dummy" material="dc15_a01_case_f_dummy_material"/>
              <geom type="mesh" class="collision" pos="-0.00967377 -0.0406146 -0.01625" quat="0.55622 0.436599 -0.55622 0.436599" mesh="dc15_a01_case_f_dummy" material="dc15_a01_case_f_dummy_material"/>
              <!-- Part dc15_a01_case_b_dummy_5 -->
              <geom type="mesh" class="visual" pos="-0.00504206 -0.0216726 -0.01625" quat="0.55622 0.436599 -0.55622 0.436599" mesh="dc15_a01_case_b_dummy" material="dc15_a01_case_b_dummy_material"/>
              <geom type="mesh" class="collision" pos="-0.00504206 -0.0216726 -0.01625" quat="0.55622 0.436599 -0.55622 0.436599" mesh="dc15_a01_case_b_dummy" material="dc15_a01_case_b_dummy_material"/>
              <!-- Part dc15_a01_horn_idle2_dummy_5 -->
              <geom type="mesh" class="visual" pos="-0.0050183 -0.0215755 -0.01625" quat="0.436599 -0.55622 -0.436599 -0.55622" mesh="dc15_a01_horn_idle2_dummy" material="dc15_a01_horn_idle2_dummy_material"/>
              <geom type="mesh" class="collision" pos="-0.0050183 -0.0215755 -0.01625" quat="0.436599 -0.55622 -0.436599 -0.55622" mesh="dc15_a01_horn_idle2_dummy" material="dc15_a01_horn_idle2_dummy_material"/>
              <!-- Part dc15_a01_idle_cap_dummy_5 -->
              <geom type="mesh" class="visual" pos="-0.00437699 -0.0189528 -0.01625" quat="0.70203 -0.0845846 -0.70203 -0.0845846" mesh="dc15_a01_idle_cap_dummy" material="dc15_a01_idle_cap_dummy_material"/>
              <geom type="mesh" class="collision" pos="-0.00437699 -0.0189528 -0.01625" quat="0.70203 -0.0845846 -0.70203 -0.0845846" mesh="dc15_a01_idle_cap_dummy" material="dc15_a01_idle_cap_dummy_material"/>
              <!-- Link lamp_head -->
              <body name="lamp_head" pos="-0.0111702 -0.0467343 -0.01625" quat="0.55622 -0.436599 0.55622 0.436599">
                <!-- Joint from angle_joint to lamp_head -->
                <joint axis="0 0 1" name="5" type="hinge" range="0.0 6.283185307179586" class="sts3215"/>
                <inertial pos="-1.29122e-07 1.66808e-08 -0.0356164" mass="0.0121476" fullinertia="1.25237e-05 1.25237e-05 1.09368e-05 -4.37816e-12 -2.51697e-11 3.08887e-11"/>
                <!-- Part lamp_head -->
                <geom type="mesh" class="visual" pos="2.60209e-18 0 -0.08014" quat="1 0 -1.11022e-16 -1.11022e-16" mesh="lamp_head" material="lamp_head_material"/>
                <geom type="mesh" class="collision" pos="2.60209e-18 0 -0.08014" quat="1 0 -1.11022e-16 -1.11022e-16" mesh="lamp_head" material="lamp_head_material"/>
              </body>
            </body>
          </body>
        </body>
      </body>
    </body>
  </worldbody>
  <asset>
    <mesh file="lamp_head.stl"/>
    <mesh file="dc15_a01_case_b_dummy.stl"/>
    <mesh file="arm_length_15cm.stl"/>
    <mesh file="dc15_a01_horn_dummy.stl"/>
    <mesh file="b3b_eh.stl"/>
    <mesh file="dc15_a01_horn_idle2_dummy.stl"/>
    <mesh file="square_joint.stl"/>
    <mesh file="dc15_a01_led_cap2_dummy.stl"/>
    <mesh file="angle_joint.stl"/>
    <mesh file="arm_length_10cm.stl"/>
    <mesh file="dc15_a01_case_m_dummy.stl"/>
    <mesh file="dc15_a01_idle_cap_dummy.stl"/>
    <mesh file="dc15_a01_case_f_dummy.stl"/>
    <mesh file="bts2_m2_6x8.stl"/>
    <mesh file="base.stl"/>
    <material name="base_material" rgba="0.615686 0.811765 0.929412 1"/>
    <material name="dc15_a01_led_cap2_dummy_material" rgba="0.768627 0.886275 0.952941 1"/>
    <material name="bts2_m2_6x8_material" rgba="0.980392 0.713725 0.00392157 1"/>
    <material name="b3b_eh_material" rgba="0.972549 0.529412 0.00392157 1"/>
    <material name="dc15_a01_case_m_dummy_material" rgba="0.615686 0.811765 0.929412 1"/>
    <material name="dc15_a01_horn_dummy_material" rgba="0.972549 0.529412 0.00392157 1"/>
    <material name="dc15_a01_case_f_dummy_material" rgba="0.980392 0.713725 0.00392157 1"/>
    <material name="dc15_a01_case_b_dummy_material" rgba="0.498039 0.498039 0.498039 1"/>
    <material name="dc15_a01_horn_idle2_dummy_material" rgba="0.647059 0.647059 0.647059 1"/>
    <material name="dc15_a01_idle_cap_dummy_material" rgba="0.615686 0.811765 0.929412 1"/>
    <material name="square_joint_material" rgba="0.615686 0.811765 0.929412 1"/>
    <material name="arm_length_15cm_material" rgba="0.615686 0.811765 0.929412 1"/>
    <material name="arm_length_10cm_material" rgba="0.615686 0.811765 0.929412 1"/>
    <material name="angle_joint_material" rgba="0.615686 0.811765 0.929412 1"/>
    <material name="lamp_head_material" rgba="0.615686 0.811765 0.929412 1"/>
  </asset>
  <actuator>
    <position class="sts3215" name="1" joint="1" inheritrange="1"/>
    <position class="sts3215" name="2" joint="2" inheritrange="1"/>
    <position class="sts3215" name="3" joint="3" inheritrange="1"/>
    <position class="sts3215" name="4" joint="4" inheritrange="1"/>
    <position class="sts3215" name="5" joint="5" inheritrange="1"/>
  </actuator>
  <equality/>
</mujoco>
