<?xml version="1.0" ?>
<!-- Generated using onshape-to-robot -->
<!-- Onshape document_id: 7ff6d1fd85a1383ea9f71557 -->
<mujoco model="lelamp">
  <compiler angle="radian" meshdir="assets" autolimits="true"/>
  <default>
    <default class="lelamp">
      <joint frictionloss="0.1" armature="0.005"/>
      <position kp="50" dampratio="1"/>
      <default class="visual">
        <geom type="mesh" contype="0" conaffinity="0" group="2"/>
      </default>
      <default class="collision">
        <geom group="3"/>
      </default>
    </default>
  </default>
  <worldbody>
    <!-- Link dc15_a01_dummy_assy_idle_asm -->
    <body name="dc15_a01_dummy_assy_idle_asm" pos="0 0 0" quat="1 0 0 0" childclass="lelamp">
      <freejoint name="dc15_a01_dummy_assy_idle_asm_freejoint"/>
      <inertial pos="-1.88967e-06 0.00939762 -0.00732928" mass="0.140913" fullinertia="9.08799e-05 0.000163373 8.05617e-05 1.89009e-09 -1.81155e-09 -1.28621e-07"/>
      <!-- Part base -->
      <geom type="mesh" class="visual" pos="-1.73472e-18 0.0008 -0.0075" quat="0.707107 -0.707107 0 0" mesh="base" material="base_material"/>
      <geom type="mesh" class="collision" pos="-1.73472e-18 0.0008 -0.0075" quat="0.707107 -0.707107 0 0" mesh="base" material="base_material"/>
      <!-- Part dc15_a01_led_cap2_dummy -->
      <geom type="mesh" class="visual" pos="0 0.0047 0.0075" quat="0.707107 0.707107 -0 -0" mesh="dc15_a01_led_cap2_dummy" material="dc15_a01_led_cap2_dummy_material"/>
      <geom type="mesh" class="collision" pos="0 0.0047 0.0075" quat="0.707107 0.707107 -0 -0" mesh="dc15_a01_led_cap2_dummy" material="dc15_a01_led_cap2_dummy_material"/>
      <!-- Part bts2_m2_6x8 -->
      <geom type="mesh" class="visual" pos="0 0.0272 0" quat="1 0 0 0" mesh="bts2_m2_6x8" material="bts2_m2_6x8_material"/>
      <geom type="mesh" class="collision" pos="0 0.0272 0" quat="1 0 0 0" mesh="bts2_m2_6x8" material="bts2_m2_6x8_material"/>
      <!-- Part b3b_eh -->
      <geom type="mesh" class="visual" pos="0.0077 0.0119 -0.009" quat="0 -0.707107 0 -0.707107" mesh="b3b_eh" material="b3b_eh_material"/>
      <geom type="mesh" class="collision" pos="0.0077 0.0119 -0.009" quat="0 -0.707107 0 -0.707107" mesh="b3b_eh" material="b3b_eh_material"/>
      <!-- Part b3b_eh_2 -->
      <geom type="mesh" class="visual" pos="-0.0077 0.0119 -0.009" quat="0 -0.707107 0 0.707107" mesh="b3b_eh" material="b3b_eh_material"/>
      <geom type="mesh" class="collision" pos="-0.0077 0.0119 -0.009" quat="0 -0.707107 0 0.707107" mesh="b3b_eh" material="b3b_eh_material"/>
      <!-- Part dc15_a01_case_m_dummy -->
      <geom type="mesh" class="visual" pos="0 0.0223 0" quat="0 0 0.707107 0.707107" mesh="dc15_a01_case_m_dummy" material="dc15_a01_case_m_dummy_material"/>
      <geom type="mesh" class="collision" pos="0 0.0223 0" quat="0 0 0.707107 0.707107" mesh="dc15_a01_case_m_dummy" material="dc15_a01_case_m_dummy_material"/>
      <!-- Part bts2_m2_6x8_2 -->
      <geom type="mesh" class="visual" pos="0 0.0016 0" quat="0 0 0 1" mesh="bts2_m2_6x8" material="bts2_m2_6x8_material"/>
      <geom type="mesh" class="collision" pos="0 0.0016 0" quat="0 0 0 1" mesh="bts2_m2_6x8" material="bts2_m2_6x8_material"/>
      <!-- Part dc15_a01_horn_dummy -->
      <geom type="mesh" class="visual" pos="0 0.0259 0" quat="1 0 0 0" mesh="dc15_a01_horn_dummy" material="dc15_a01_horn_dummy_material"/>
      <geom type="mesh" class="collision" pos="0 0.0259 0" quat="1 0 0 0" mesh="dc15_a01_horn_dummy" material="dc15_a01_horn_dummy_material"/>
      <!-- Part dc15_a01_case_f_dummy -->
      <geom type="mesh" class="visual" pos="0 0.0223 0" quat="0 0 0.707107 0.707107" mesh="dc15_a01_case_f_dummy" material="dc15_a01_case_f_dummy_material"/>
      <geom type="mesh" class="collision" pos="0 0.0223 0" quat="0 0 0.707107 0.707107" mesh="dc15_a01_case_f_dummy" material="dc15_a01_case_f_dummy_material"/>
      <!-- Part dc15_a01_case_b_dummy -->
      <geom type="mesh" class="visual" pos="0 0.0028 0" quat="0 0 0.707107 0.707107" mesh="dc15_a01_case_b_dummy" material="dc15_a01_case_b_dummy_material"/>
      <geom type="mesh" class="collision" pos="0 0.0028 0" quat="0 0 0.707107 0.707107" mesh="dc15_a01_case_b_dummy" material="dc15_a01_case_b_dummy_material"/>
      <!-- Part dc15_a01_horn_idle2_dummy -->
      <geom type="mesh" class="visual" pos="0 0.0027 0" quat="0 0 -0.707107 0.707107" mesh="dc15_a01_horn_idle2_dummy" material="dc15_a01_horn_idle2_dummy_material"/>
      <geom type="mesh" class="collision" pos="0 0.0027 0" quat="0 0 -0.707107 0.707107" mesh="dc15_a01_horn_idle2_dummy" material="dc15_a01_horn_idle2_dummy_material"/>
      <!-- Part dc15_a01_idle_cap_dummy -->
      <geom type="mesh" class="visual" pos="0 -7.80626e-18 0" quat="0 0 0 1" mesh="dc15_a01_idle_cap_dummy" material="dc15_a01_idle_cap_dummy_material"/>
      <geom type="mesh" class="collision" pos="0 -7.80626e-18 0" quat="0 0 0 1" mesh="dc15_a01_idle_cap_dummy" material="dc15_a01_idle_cap_dummy_material"/>
      <!-- Link square_joint -->
      <body name="square_joint" pos="2.71051e-20 0.0286 -6.50521e-19" quat="0.0155579 -0.0155579 0.706936 0.706936">
        <!-- Joint from dc15_a01_dummy_assy_idle_asm to square_joint -->
        <joint axis="0 0 1" name="1" type="hinge"/>
        <inertial pos="-8.75044e-06 -0.000538186 0.0283784" mass="0.0304303" fullinertia="6.68219e-06 6.31947e-06 3.33001e-06 6.6143e-10 -1.534e-09 -1.78501e-07"/>
        <!-- Part square_joint -->
        <geom type="mesh" class="visual" pos="-5.83045e-36 0 0" quat="1 0 0 0" mesh="square_joint" material="square_joint_material"/>
        <geom type="mesh" class="collision" pos="-5.83045e-36 0 0" quat="1 0 0 0" mesh="square_joint" material="square_joint_material"/>
        <!-- Part dc15_a01_led_cap2_dummy_2 -->
        <geom type="mesh" class="visual" pos="-8.35134e-18 -0.00985 0.04425" quat="0.707107 0.707107 0 3.02204e-19" mesh="dc15_a01_led_cap2_dummy" material="dc15_a01_led_cap2_dummy_material"/>
        <geom type="mesh" class="collision" pos="-8.35134e-18 -0.00985 0.04425" quat="0.707107 0.707107 0 3.02204e-19" mesh="dc15_a01_led_cap2_dummy" material="dc15_a01_led_cap2_dummy_material"/>
        <!-- Part bts2_m2_6x8_3 -->
        <geom type="mesh" class="visual" pos="2.12657e-18 0.01265 0.03675" quat="1 0 0 0" mesh="bts2_m2_6x8" material="bts2_m2_6x8_material"/>
        <geom type="mesh" class="collision" pos="2.12657e-18 0.01265 0.03675" quat="1 0 0 0" mesh="bts2_m2_6x8" material="bts2_m2_6x8_material"/>
        <!-- Part b3b_eh_3 -->
        <geom type="mesh" class="visual" pos="0.0077 -0.00265 0.02775" quat="4.66333e-19 0.707107 -0 0.707107" mesh="b3b_eh" material="b3b_eh_material"/>
        <geom type="mesh" class="collision" pos="0.0077 -0.00265 0.02775" quat="4.66333e-19 0.707107 -0 0.707107" mesh="b3b_eh" material="b3b_eh_material"/>
        <!-- Part b3b_eh_4 -->
        <geom type="mesh" class="visual" pos="-0.0077 -0.00265 0.02775" quat="4.66333e-19 -0.707107 0 0.707107" mesh="b3b_eh" material="b3b_eh_material"/>
        <geom type="mesh" class="collision" pos="-0.0077 -0.00265 0.02775" quat="4.66333e-19 -0.707107 0 0.707107" mesh="b3b_eh" material="b3b_eh_material"/>
        <!-- Part dc15_a01_case_m_dummy_2 -->
        <geom type="mesh" class="visual" pos="-5.2338e-18 0.00775 0.03675" quat="1.71728e-18 0 -0.707107 -0.707107" mesh="dc15_a01_case_m_dummy" material="dc15_a01_case_m_dummy_material"/>
        <geom type="mesh" class="collision" pos="-5.2338e-18 0.00775 0.03675" quat="1.71728e-18 0 -0.707107 -0.707107" mesh="dc15_a01_case_m_dummy" material="dc15_a01_case_m_dummy_material"/>
        <!-- Part bts2_m2_6x8_4 -->
        <geom type="mesh" class="visual" pos="-3.14793e-18 -0.01295 0.03675" quat="0 0 0 1" mesh="bts2_m2_6x8" material="bts2_m2_6x8_material"/>
        <geom type="mesh" class="collision" pos="-3.14793e-18 -0.01295 0.03675" quat="0 0 0 1" mesh="bts2_m2_6x8" material="bts2_m2_6x8_material"/>
        <!-- Part dc15_a01_horn_dummy_2 -->
        <geom type="mesh" class="visual" pos="1.44112e-20 0.01135 0.03675" quat="1 0 0 0" mesh="dc15_a01_horn_dummy" material="dc15_a01_horn_dummy_material"/>
        <geom type="mesh" class="collision" pos="1.44112e-20 0.01135 0.03675" quat="1 0 0 0" mesh="dc15_a01_horn_dummy" material="dc15_a01_horn_dummy_material"/>
        <!-- Part dc15_a01_case_f_dummy_2 -->
        <geom type="mesh" class="visual" pos="-5.2338e-18 0.00775 0.03675" quat="1.71728e-18 0 -0.707107 -0.707107" mesh="dc15_a01_case_f_dummy" material="dc15_a01_case_f_dummy_material"/>
        <geom type="mesh" class="collision" pos="-5.2338e-18 0.00775 0.03675" quat="1.71728e-18 0 -0.707107 -0.707107" mesh="dc15_a01_case_f_dummy" material="dc15_a01_case_f_dummy_material"/>
        <!-- Part dc15_a01_case_b_dummy_2 -->
        <geom type="mesh" class="visual" pos="-3.4043e-18 -0.01175 0.03675" quat="1.71728e-18 0 -0.707107 -0.707107" mesh="dc15_a01_case_b_dummy" material="dc15_a01_case_b_dummy_material"/>
        <geom type="mesh" class="collision" pos="-3.4043e-18 -0.01175 0.03675" quat="1.71728e-18 0 -0.707107 -0.707107" mesh="dc15_a01_case_b_dummy" material="dc15_a01_case_b_dummy_material"/>
        <!-- Part dc15_a01_horn_idle2_dummy_2 -->
        <geom type="mesh" class="visual" pos="-6.61309e-19 -0.01185 0.03675" quat="1.71728e-18 0 0.707107 -0.707107" mesh="dc15_a01_horn_idle2_dummy" material="dc15_a01_horn_idle2_dummy_material"/>
        <geom type="mesh" class="collision" pos="-6.61309e-19 -0.01185 0.03675" quat="1.71728e-18 0 0.707107 -0.707107" mesh="dc15_a01_horn_idle2_dummy" material="dc15_a01_horn_idle2_dummy_material"/>
        <!-- Part dc15_a01_idle_cap_dummy_2 -->
        <geom type="mesh" class="visual" pos="-1.47751e-17 -0.01455 0.03675" quat="0 0 0 1" mesh="dc15_a01_idle_cap_dummy" material="dc15_a01_idle_cap_dummy_material"/>
        <geom type="mesh" class="collision" pos="-1.47751e-17 -0.01455 0.03675" quat="0 0 0 1" mesh="dc15_a01_idle_cap_dummy" material="dc15_a01_idle_cap_dummy_material"/>
        <!-- Link dc15_a01_dummy_assy_idle_asm_2 -->
        <body name="dc15_a01_dummy_assy_idle_asm_2" pos="5.72708e-21 0.01405 0.03675" quat="0.707107 -0.707107 -0 3.02204e-19">
          <!-- Joint from square_joint to dc15_a01_dummy_assy_idle_asm_2 -->
          <joint axis="0 0 1" name="3" type="hinge"/>
          <inertial pos="0.0876363 -0.123134 -0.0137912" mass="0.0439213" fullinertia="0.000130113 6.81333e-05 0.000192616 8.9603e-05 -5.40198e-07 7.5607e-07"/>
          <!-- Part arm_length_15cm -->
          <geom type="mesh" class="visual" pos="6.88141e-18 -2.77556e-17 0.002" quat="2.6062e-17 0.952671 0.304002 -4.03094e-17" mesh="arm_length_15cm" material="arm_length_15cm_material"/>
          <geom type="mesh" class="collision" pos="6.88141e-18 -2.77556e-17 0.002" quat="2.6062e-17 0.952671 0.304002 -4.03094e-17" mesh="arm_length_15cm" material="arm_length_15cm_material"/>
          <!-- Part dc15_a01_led_cap2_dummy_3 -->
          <geom type="mesh" class="visual" pos="0.119959 -0.168391 -0.0231" quat="1.33089e-15 0.952671 0.304002 -1.02696e-15" mesh="dc15_a01_led_cap2_dummy" material="dc15_a01_led_cap2_dummy_material"/>
          <geom type="mesh" class="collision" pos="0.119959 -0.168391 -0.0231" quat="1.33089e-15 0.952671 0.304002 -1.02696e-15" mesh="dc15_a01_led_cap2_dummy" material="dc15_a01_led_cap2_dummy_material"/>
          <!-- Part bts2_m2_6x8_5 -->
          <geom type="mesh" class="visual" pos="0.115615 -0.162277 -0.0006" quat="0.67364 0.67364 0.214962 0.214962" mesh="bts2_m2_6x8" material="bts2_m2_6x8_material"/>
          <geom type="mesh" class="collision" pos="0.115615 -0.162277 -0.0006" quat="0.67364 0.67364 0.214962 0.214962" mesh="bts2_m2_6x8" material="bts2_m2_6x8_material"/>
          <!-- Part b3b_eh_5 -->
          <geom type="mesh" class="visual" pos="0.116679 -0.15048 -0.0159" quat="0.628337 -0.628337 0.324335 -0.324335" mesh="b3b_eh" material="b3b_eh_material"/>
          <geom type="mesh" class="collision" pos="0.116679 -0.15048 -0.0159" quat="0.628337 -0.628337 0.324335 -0.324335" mesh="b3b_eh" material="b3b_eh_material"/>
          <!-- Part b3b_eh_6 -->
          <geom type="mesh" class="visual" pos="0.104125 -0.1594 -0.0159" quat="0.324335 -0.324335 -0.628337 0.628337" mesh="b3b_eh" material="b3b_eh_material"/>
          <geom type="mesh" class="collision" pos="0.104125 -0.1594 -0.0159" quat="0.324335 -0.324335 -0.628337 0.628337" mesh="b3b_eh" material="b3b_eh_material"/>
          <!-- Part dc15_a01_case_m_dummy_3 -->
          <geom type="mesh" class="visual" pos="0.115615 -0.162277 -0.0055" quat="0.304002 -1.02696e-15 -1.27676e-15 -0.952671" mesh="dc15_a01_case_m_dummy" material="dc15_a01_case_m_dummy_material"/>
          <geom type="mesh" class="collision" pos="0.115615 -0.162277 -0.0055" quat="0.304002 -1.02696e-15 -1.27676e-15 -0.952671" mesh="dc15_a01_case_m_dummy" material="dc15_a01_case_m_dummy_material"/>
          <!-- Part bts2_m2_6x8_6 -->
          <geom type="mesh" class="visual" pos="0.115615 -0.162277 -0.0262" quat="0.214962 -0.214962 0.67364 -0.67364" mesh="bts2_m2_6x8" material="bts2_m2_6x8_material"/>
          <geom type="mesh" class="collision" pos="0.115615 -0.162277 -0.0262" quat="0.214962 -0.214962 0.67364 -0.67364" mesh="bts2_m2_6x8" material="bts2_m2_6x8_material"/>
          <!-- Part dc15_a01_horn_dummy_3 -->
          <geom type="mesh" class="visual" pos="0.115615 -0.162277 -0.0019" quat="0.67364 0.67364 0.214962 0.214962" mesh="dc15_a01_horn_dummy" material="dc15_a01_horn_dummy_material"/>
          <geom type="mesh" class="collision" pos="0.115615 -0.162277 -0.0019" quat="0.67364 0.67364 0.214962 0.214962" mesh="dc15_a01_horn_dummy" material="dc15_a01_horn_dummy_material"/>
          <!-- Part dc15_a01_case_f_dummy_3 -->
          <geom type="mesh" class="visual" pos="0.115615 -0.162277 -0.0055" quat="0.304002 -1.02696e-15 -1.27676e-15 -0.952671" mesh="dc15_a01_case_f_dummy" material="dc15_a01_case_f_dummy_material"/>
          <geom type="mesh" class="collision" pos="0.115615 -0.162277 -0.0055" quat="0.304002 -1.02696e-15 -1.27676e-15 -0.952671" mesh="dc15_a01_case_f_dummy" material="dc15_a01_case_f_dummy_material"/>
          <!-- Part dc15_a01_case_b_dummy_3 -->
          <geom type="mesh" class="visual" pos="0.115615 -0.162277 -0.025" quat="0.304002 -1.02696e-15 -1.27676e-15 -0.952671" mesh="dc15_a01_case_b_dummy" material="dc15_a01_case_b_dummy_material"/>
          <geom type="mesh" class="collision" pos="0.115615 -0.162277 -0.025" quat="0.304002 -1.02696e-15 -1.27676e-15 -0.952671" mesh="dc15_a01_case_b_dummy" material="dc15_a01_case_b_dummy_material"/>
          <!-- Part dc15_a01_horn_idle2_dummy_3 -->
          <geom type="mesh" class="visual" pos="0.115615 -0.162277 -0.0251" quat="1.14024e-15 0.304002 -0.952671 1.31734e-15" mesh="dc15_a01_horn_idle2_dummy" material="dc15_a01_horn_idle2_dummy_material"/>
          <geom type="mesh" class="collision" pos="0.115615 -0.162277 -0.0251" quat="1.14024e-15 0.304002 -0.952671 1.31734e-15" mesh="dc15_a01_horn_idle2_dummy" material="dc15_a01_horn_idle2_dummy_material"/>
          <!-- Part dc15_a01_idle_cap_dummy_3 -->
          <geom type="mesh" class="visual" pos="0.115615 -0.162277 -0.0278" quat="0.214962 -0.214962 0.67364 -0.67364" mesh="dc15_a01_idle_cap_dummy" material="dc15_a01_idle_cap_dummy_material"/>
          <geom type="mesh" class="collision" pos="0.115615 -0.162277 -0.0278" quat="0.214962 -0.214962 0.67364 -0.67364" mesh="dc15_a01_idle_cap_dummy" material="dc15_a01_idle_cap_dummy_material"/>
          <!-- Link arm_length_10cm -->
          <body name="arm_length_10cm" pos="0.115615 -0.162277 0.0008" quat="0.740133 -1.94688e-15 1.77636e-15 -0.67246">
            <!-- Joint from dc15_a01_dummy_assy_idle_asm_2 to arm_length_10cm -->
            <joint axis="0 0 1" name="2" type="hinge"/>
            <inertial pos="0.000125498 -0.115742 -0.013751" mass="0.040387" fullinertia="9.51594e-05 4.19848e-06 9.39396e-05 1.396e-07 -2.20999e-09 6.104e-07"/>
            <!-- Part arm_length_10cm -->
            <geom type="mesh" class="visual" pos="2.77556e-17 1.38778e-17 0.002" quat="0 1 0 0" mesh="arm_length_10cm" material="arm_length_10cm_material"/>
            <geom type="mesh" class="collision" pos="2.77556e-17 1.38778e-17 0.002" quat="0 1 0 0" mesh="arm_length_10cm" material="arm_length_10cm_material"/>
            <!-- Part dc15_a01_led_cap2_dummy_4 -->
            <geom type="mesh" class="visual" pos="0.00025 -0.15675 -0.0231" quat="1.43063e-16 -1 -3.12803e-16 6.3944e-16" mesh="dc15_a01_led_cap2_dummy" material="dc15_a01_led_cap2_dummy_material"/>
            <geom type="mesh" class="collision" pos="0.00025 -0.15675 -0.0231" quat="1.43063e-16 -1 -3.12803e-16 6.3944e-16" mesh="dc15_a01_led_cap2_dummy" material="dc15_a01_led_cap2_dummy_material"/>
            <!-- Part bts2_m2_6x8_7 -->
            <geom type="mesh" class="visual" pos="0.00025 -0.14925 -0.0006" quat="0.707107 0.707107 1.15463e-14 2.26265e-15" mesh="bts2_m2_6x8" material="bts2_m2_6x8_material"/>
            <geom type="mesh" class="collision" pos="0.00025 -0.14925 -0.0006" quat="0.707107 0.707107 1.15463e-14 2.26265e-15" mesh="bts2_m2_6x8" material="bts2_m2_6x8_material"/>
            <!-- Part b3b_eh_7 -->
            <geom type="mesh" class="visual" pos="0.00795 -0.14025 -0.0159" quat="0.5 -0.5 0.5 -0.5" mesh="b3b_eh" material="b3b_eh_material"/>
            <geom type="mesh" class="collision" pos="0.00795 -0.14025 -0.0159" quat="0.5 -0.5 0.5 -0.5" mesh="b3b_eh" material="b3b_eh_material"/>
            <!-- Part b3b_eh_8 -->
            <geom type="mesh" class="visual" pos="-0.00745 -0.14025 -0.0159" quat="0.5 -0.5 -0.5 0.5" mesh="b3b_eh" material="b3b_eh_material"/>
            <geom type="mesh" class="collision" pos="-0.00745 -0.14025 -0.0159" quat="0.5 -0.5 -0.5 0.5" mesh="b3b_eh" material="b3b_eh_material"/>
            <!-- Part dc15_a01_case_m_dummy_4 -->
            <geom type="mesh" class="visual" pos="0.00025 -0.14925 -0.0055" quat="2.77556e-16 -6.33202e-16 2.22045e-16 -1" mesh="dc15_a01_case_m_dummy" material="dc15_a01_case_m_dummy_material"/>
            <geom type="mesh" class="collision" pos="0.00025 -0.14925 -0.0055" quat="2.77556e-16 -6.33202e-16 2.22045e-16 -1" mesh="dc15_a01_case_m_dummy" material="dc15_a01_case_m_dummy_material"/>
            <!-- Part bts2_m2_6x8_8 -->
            <geom type="mesh" class="visual" pos="0.00025 -0.14925 -0.0262" quat="2.44249e-14 2.48642e-15 0.707107 -0.707107" mesh="bts2_m2_6x8" material="bts2_m2_6x8_material"/>
            <geom type="mesh" class="collision" pos="0.00025 -0.14925 -0.0262" quat="2.44249e-14 2.48642e-15 0.707107 -0.707107" mesh="bts2_m2_6x8" material="bts2_m2_6x8_material"/>
            <!-- Part dc15_a01_horn_dummy_4 -->
            <geom type="mesh" class="visual" pos="0.00025 -0.14925 -0.0019" quat="0.707107 0.707107 1.15463e-14 2.26265e-15" mesh="dc15_a01_horn_dummy" material="dc15_a01_horn_dummy_material"/>
            <geom type="mesh" class="collision" pos="0.00025 -0.14925 -0.0019" quat="0.707107 0.707107 1.15463e-14 2.26265e-15" mesh="dc15_a01_horn_dummy" material="dc15_a01_horn_dummy_material"/>
            <!-- Part dc15_a01_case_f_dummy_4 -->
            <geom type="mesh" class="visual" pos="0.00025 -0.14925 -0.0055" quat="2.77556e-16 -6.33202e-16 2.22045e-16 -1" mesh="dc15_a01_case_f_dummy" material="dc15_a01_case_f_dummy_material"/>
            <geom type="mesh" class="collision" pos="0.00025 -0.14925 -0.0055" quat="2.77556e-16 -6.33202e-16 2.22045e-16 -1" mesh="dc15_a01_case_f_dummy" material="dc15_a01_case_f_dummy_material"/>
            <!-- Part dc15_a01_case_b_dummy_4 -->
            <geom type="mesh" class="visual" pos="0.00025 -0.14925 -0.025" quat="2.77556e-16 -6.33202e-16 2.22045e-16 -1" mesh="dc15_a01_case_b_dummy" material="dc15_a01_case_b_dummy_material"/>
            <geom type="mesh" class="collision" pos="0.00025 -0.14925 -0.025" quat="2.77556e-16 -6.33202e-16 2.22045e-16 -1" mesh="dc15_a01_case_b_dummy" material="dc15_a01_case_b_dummy_material"/>
            <!-- Part dc15_a01_horn_idle2_dummy_4 -->
            <geom type="mesh" class="visual" pos="0.00025 -0.14925 -0.0251" quat="1.65215e-14 -2.89552e-14 1 3.22485e-15" mesh="dc15_a01_horn_idle2_dummy" material="dc15_a01_horn_idle2_dummy_material"/>
            <geom type="mesh" class="collision" pos="0.00025 -0.14925 -0.0251" quat="1.65215e-14 -2.89552e-14 1 3.22485e-15" mesh="dc15_a01_horn_idle2_dummy" material="dc15_a01_horn_idle2_dummy_material"/>
            <!-- Part dc15_a01_idle_cap_dummy_4 -->
            <geom type="mesh" class="visual" pos="0.00025 -0.14925 -0.0278" quat="2.44249e-14 2.48642e-15 0.707107 -0.707107" mesh="dc15_a01_idle_cap_dummy" material="dc15_a01_idle_cap_dummy_material"/>
            <geom type="mesh" class="collision" pos="0.00025 -0.14925 -0.0278" quat="2.44249e-14 2.48642e-15 0.707107 -0.707107" mesh="dc15_a01_idle_cap_dummy" material="dc15_a01_idle_cap_dummy_material"/>
            <!-- Link angle_joint -->
            <body name="angle_joint" pos="0.00025 -0.14925 0.0008" quat="1 -1.18145e-14 6.21725e-15 9.6867e-15">
              <!-- Joint from arm_length_10cm to angle_joint -->
              <joint axis="0 0 1" name="4" type="hinge"/>
              <inertial pos="-0.00767354 -0.0293086 -0.0162582" mass="0.0271577" fullinertia="5.36408e-06 3.96054e-06 6.2876e-06 -1.97814e-07 -2.8704e-09 5.88823e-09"/>
              <!-- Part angle_joint -->
              <geom type="mesh" class="visual" pos="8.60423e-16 1.94289e-16 5.20417e-17" quat="1.38756e-15 -0.974166 0.225831 -1.27668e-15" mesh="angle_joint" material="angle_joint_material"/>
              <geom type="mesh" class="collision" pos="8.60423e-16 1.94289e-16 5.20417e-17" quat="1.38756e-15 -0.974166 0.225831 -1.27668e-15" mesh="angle_joint" material="angle_joint_material"/>
              <!-- Part dc15_a01_led_cap2_dummy_5 -->
              <geom type="mesh" class="visual" pos="-0.0171364 -0.0184968 -0.01625" quat="0.599999 -0.374168 0.599999 0.374168" mesh="dc15_a01_led_cap2_dummy" material="dc15_a01_led_cap2_dummy_material"/>
              <geom type="mesh" class="collision" pos="-0.0171364 -0.0184968 -0.01625" quat="0.599999 -0.374168 0.599999 0.374168" mesh="dc15_a01_led_cap2_dummy" material="dc15_a01_led_cap2_dummy_material"/>
              <!-- Part bts2_m2_6x8_9 -->
              <geom type="mesh" class="visual" pos="-0.0203012 -0.0420017 -0.01625" quat="0.159687 -0.68884 0.159687 0.68884" mesh="bts2_m2_6x8" material="bts2_m2_6x8_material"/>
              <geom type="mesh" class="collision" pos="-0.0203012 -0.0420017 -0.01625" quat="0.159687 -0.68884 0.159687 0.68884" mesh="bts2_m2_6x8" material="bts2_m2_6x8_material"/>
              <!-- Part b3b_eh_9 -->
              <geom type="mesh" class="visual" pos="-0.00548731 -0.0322223 -0.02395" quat="1.55668e-15 -0.225831 -0.974166 1.15056e-14" mesh="b3b_eh" material="b3b_eh_material"/>
              <geom type="mesh" class="collision" pos="-0.00548731 -0.0322223 -0.02395" quat="1.55668e-15 -0.225831 -0.974166 1.15056e-14" mesh="b3b_eh" material="b3b_eh_material"/>
              <!-- Part b3b_eh_10 -->
              <geom type="mesh" class="visual" pos="-0.00548731 -0.0322223 -0.00855" quat="0.974166 -1.15485e-14 1.77636e-15 -0.225831" mesh="b3b_eh" material="b3b_eh_material"/>
              <geom type="mesh" class="collision" pos="-0.00548731 -0.0322223 -0.00855" quat="0.974166 -1.15485e-14 1.77636e-15 -0.225831" mesh="b3b_eh" material="b3b_eh_material"/>
              <!-- Part dc15_a01_case_m_dummy_5 -->
              <geom type="mesh" class="visual" pos="-0.0181453 -0.0376015 -0.01625" quat="0.599999 0.374168 -0.599999 0.374168" mesh="dc15_a01_case_m_dummy" material="dc15_a01_case_m_dummy_material"/>
              <geom type="mesh" class="collision" pos="-0.0181453 -0.0376015 -0.01625" quat="0.599999 0.374168 -0.599999 0.374168" mesh="dc15_a01_case_m_dummy" material="dc15_a01_case_m_dummy_material"/>
              <!-- Part bts2_m2_6x8_10 -->
              <geom type="mesh" class="visual" pos="-0.00903738 -0.0190129 -0.01625" quat="0.68884 -0.159687 -0.68884 -0.159687" mesh="bts2_m2_6x8" material="bts2_m2_6x8_material"/>
              <geom type="mesh" class="collision" pos="-0.00903738 -0.0190129 -0.01625" quat="0.68884 -0.159687 -0.68884 -0.159687" mesh="bts2_m2_6x8" material="bts2_m2_6x8_material"/>
              <!-- Part dc15_a01_horn_dummy_5 -->
              <geom type="mesh" class="visual" pos="-0.0197292 -0.0408343 -0.01625" quat="0.159687 -0.68884 0.159687 0.68884" mesh="dc15_a01_horn_dummy" material="dc15_a01_horn_dummy_material"/>
              <geom type="mesh" class="collision" pos="-0.0197292 -0.0408343 -0.01625" quat="0.159687 -0.68884 0.159687 0.68884" mesh="dc15_a01_horn_dummy" material="dc15_a01_horn_dummy_material"/>
              <!-- Part dc15_a01_case_f_dummy_5 -->
              <geom type="mesh" class="visual" pos="-0.0181453 -0.0376015 -0.01625" quat="0.599999 0.374168 -0.599999 0.374168" mesh="dc15_a01_case_f_dummy" material="dc15_a01_case_f_dummy_material"/>
              <geom type="mesh" class="collision" pos="-0.0181453 -0.0376015 -0.01625" quat="0.599999 0.374168 -0.599999 0.374168" mesh="dc15_a01_case_f_dummy" material="dc15_a01_case_f_dummy_material"/>
              <!-- Part dc15_a01_case_b_dummy_5 -->
              <geom type="mesh" class="visual" pos="-0.00956537 -0.0200905 -0.01625" quat="0.599999 0.374168 -0.599999 0.374168" mesh="dc15_a01_case_b_dummy" material="dc15_a01_case_b_dummy_material"/>
              <geom type="mesh" class="collision" pos="-0.00956537 -0.0200905 -0.01625" quat="0.599999 0.374168 -0.599999 0.374168" mesh="dc15_a01_case_b_dummy" material="dc15_a01_case_b_dummy_material"/>
              <!-- Part dc15_a01_horn_idle2_dummy_5 -->
              <geom type="mesh" class="visual" pos="-0.00952137 -0.0200007 -0.01625" quat="0.374168 -0.599999 -0.374168 -0.599999" mesh="dc15_a01_horn_idle2_dummy" material="dc15_a01_horn_idle2_dummy_material"/>
              <geom type="mesh" class="collision" pos="-0.00952137 -0.0200007 -0.01625" quat="0.374168 -0.599999 -0.374168 -0.599999" mesh="dc15_a01_horn_idle2_dummy" material="dc15_a01_horn_idle2_dummy_material"/>
              <!-- Part dc15_a01_idle_cap_dummy_5 -->
              <geom type="mesh" class="visual" pos="-0.00833339 -0.0175761 -0.01625" quat="0.68884 -0.159687 -0.68884 -0.159687" mesh="dc15_a01_idle_cap_dummy" material="dc15_a01_idle_cap_dummy_material"/>
              <geom type="mesh" class="collision" pos="-0.00833339 -0.0175761 -0.01625" quat="0.68884 -0.159687 -0.68884 -0.159687" mesh="dc15_a01_idle_cap_dummy" material="dc15_a01_idle_cap_dummy_material"/>
              <!-- Link lamp_head -->
              <body name="lamp_head" pos="-0.0209172 -0.0432589 -0.01625" quat="0.660877 -0.482819 0.51661 0.251478">
                <!-- Joint from angle_joint to lamp_head -->
                <joint axis="0 0 1" name="5" type="hinge"/>
                <inertial pos="-1.29122e-07 1.66808e-08 -0.0356164" mass="0.0121476" fullinertia="1.25237e-05 1.25237e-05 1.09368e-05 -4.37816e-12 -2.51697e-11 3.08887e-11"/>
                <!-- Part lamp_head -->
                <geom type="mesh" class="visual" pos="0 2.77556e-17 -0.08014" quat="1 0 -1.38778e-17 -2.67147e-16" mesh="lamp_head" material="lamp_head_material"/>
                <geom type="mesh" class="collision" pos="0 2.77556e-17 -0.08014" quat="1 0 -1.38778e-17 -2.67147e-16" mesh="lamp_head" material="lamp_head_material"/>
              </body>
            </body>
          </body>
        </body>
      </body>
    </body>
  </worldbody>
  <asset>
    <mesh file="dc15_a01_case_f_dummy.stl"/>
    <mesh file="lamp_head.stl"/>
    <mesh file="angle_joint.stl"/>
    <mesh file="b3b_eh.stl"/>
    <mesh file="dc15_a01_case_m_dummy.stl"/>
    <mesh file="dc15_a01_case_b_dummy.stl"/>
    <mesh file="dc15_a01_idle_cap_dummy.stl"/>
    <mesh file="square_joint.stl"/>
    <mesh file="arm_length_15cm.stl"/>
    <mesh file="bts2_m2_6x8.stl"/>
    <mesh file="dc15_a01_horn_dummy.stl"/>
    <mesh file="base.stl"/>
    <mesh file="dc15_a01_led_cap2_dummy.stl"/>
    <mesh file="arm_length_10cm.stl"/>
    <mesh file="dc15_a01_horn_idle2_dummy.stl"/>
    <material name="base_material" rgba="0.615686 0.811765 0.929412 1"/>
    <material name="dc15_a01_led_cap2_dummy_material" rgba="0.768627 0.886275 0.952941 1"/>
    <material name="bts2_m2_6x8_material" rgba="0.980392 0.713725 0.00392157 1"/>
    <material name="b3b_eh_material" rgba="0.972549 0.529412 0.00392157 1"/>
    <material name="dc15_a01_case_m_dummy_material" rgba="0.615686 0.811765 0.929412 1"/>
    <material name="dc15_a01_horn_dummy_material" rgba="0.972549 0.529412 0.00392157 1"/>
    <material name="dc15_a01_case_f_dummy_material" rgba="0.980392 0.713725 0.00392157 1"/>
    <material name="dc15_a01_case_b_dummy_material" rgba="0.498039 0.498039 0.498039 1"/>
    <material name="dc15_a01_horn_idle2_dummy_material" rgba="0.647059 0.647059 0.647059 1"/>
    <material name="dc15_a01_idle_cap_dummy_material" rgba="0.615686 0.811765 0.929412 1"/>
    <material name="square_joint_material" rgba="0.615686 0.811765 0.929412 1"/>
    <material name="arm_length_15cm_material" rgba="0.615686 0.811765 0.929412 1"/>
    <material name="arm_length_10cm_material" rgba="0.615686 0.811765 0.929412 1"/>
    <material name="angle_joint_material" rgba="0.615686 0.811765 0.929412 1"/>
    <material name="lamp_head_material" rgba="0.615686 0.811765 0.929412 1"/>
  </asset>
  <actuator>
    <position class="lelamp" name="1" joint="1"/>
    <position class="lelamp" name="3" joint="3"/>
    <position class="lelamp" name="2" joint="2"/>
    <position class="lelamp" name="4" joint="4"/>
    <position class="lelamp" name="5" joint="5"/>
  </actuator>
  <equality/>
</mujoco>
